Workbook

Sheet 현황
A1: AAIA 회원사 현황
A2: 모든 숫자는 종합 시트에서 자동 계산됩니다. 이 시트에는 입력하지 마세요.
A4: 전체 회원사 수 | B4: =COUNTIF(종합!$B$3:$B$501,"?*") -> 299
A6: 분과 | B6: 회원사 수 | C6: 분과 시트 표시
A7: 기술 | B7: =COUNTIF(종합!$C$3:$C$501,"?*") -> 129 | C7: =COUNTIF(기술분과!$B$3:$B$452,"?*") -> 129
A8: 산업 | B8: =COUNTIF(종합!$D$3:$D$501,"?*") -> 127 | C8: =COUNTIF(산업분과!$B$3:$B$452,"?*") -> 127
A9: 생태계 | B9: =COUNTIF(종합!$E$3:$E$501,"?*") -> 65 | C9: =COUNTIF(생태계분과!$B$3:$B$452,"?*") -> 65
A10: 안전·신뢰 | B10: =COUNTIF(종합!$F$3:$F$501,"?*") -> 35 | C10: =COUNTIF(안전신뢰분과!$B$3:$B$452,"?*") -> 35
A12: 기업유형 | B12: 회원사 수 | C12: 기술 | D12: 산업 | E12: 생태계 | F12: 안전·신뢰
A13: 대기업 | B13: =COUNTIF(종합!$G$3:$G$501,"대기업") -> 10 | C13: =COUNTIFS(종합!$G$3:$G$501,"대기업",종합!$C$3:$C$501,"?*") -> 3 | D13: =COUNTIFS(종합!$G$3:$G$501,"대기업",종합!$D$3:$D$501,"?*") -> 5 | E13: =COUNTIFS(종합!$G$3:$G$501,"대기업",종합!$E$3:$E$501,"?*") -> 2 | F13: =COUNTIFS(종합!$G$3:$G$501,"대기업",종합!$F$3:$F$501,"?*") -> 0
A14: 중견기업 | B14: =COUNTIF(종합!$G$3:$G$501,"중견기업") -> 18 | C14: =COUNTIFS(종합!$G$3:$G$501,"중견기업",종합!$C$3:$C$501,"?*") -> 7 | D14: =COUNTIFS(종합!$G$3:$G$501,"중견기업",종합!$D$3:$D$501,"?*") -> 7 | E14: =COUNTIFS(종합!$G$3:$G$501,"중견기업",종합!$E$3:$E$501,"?*") -> 9 | F14: =COUNTIFS(종합!$G$3:$G$501,"중견기업",종합!$F$3:$F$501,"?*") -> 1
A15: 중소기업 | B15: =COUNTIF(종합!$G$3:$G$501,"중소기업") -> 249 | C15: =COUNTIFS(종합!$G$3:$G$501,"중소기업",종합!$C$3:$C$501,"?*") -> 115 | D15: =COUNTIFS(종합!$G$3:$G$501,"중소기업",종합!$D$3:$D$501,"?*") -> 111 | E15: =COUNTIFS(종합!$G$3:$G$501,"중소기업",종합!$E$3:$E$501,"?*") -> 45 | F15: =COUNTIFS(종합!$G$3:$G$501,"중소기업",종합!$F$3:$F$501,"?*") -> 26
A16: 공공기관 | B16: =COUNTIF(종합!$G$3:$G$501,"공공기관") -> 7 | C16: =COUNTIFS(종합!$G$3:$G$501,"공공기관",종합!$C$3:$C$501,"?*") -> 2 | D16: =COUNTIFS(종합!$G$3:$G$501,"공공기관",종합!$D$3:$D$501,"?*") -> 1 | E16: =COUNTIFS(종합!$G$3:$G$501,"공공기관",종합!$E$3:$E$501,"?*") -> 1 | F16: =COUNTIFS(종합!$G$3:$G$501,"공공기관",종합!$F$3:$F$501,"?*") -> 3
A17: 대학 | B17: =COUNTIF(종합!$G$3:$G$501,"대학") -> 4 | C17: =COUNTIFS(종합!$G$3:$G$501,"대학",종합!$C$3:$C$501,"?*") -> 0 | D17: =COUNTIFS(종합!$G$3:$G$501,"대학",종합!$D$3:$D$501,"?*") -> 0 | E17: =COUNTIFS(종합!$G$3:$G$501,"대학",종합!$E$3:$E$501,"?*") -> 0 | F17: =COUNTIFS(종합!$G$3:$G$501,"대학",종합!$F$3:$F$501,"?*") -> 4
A18: 협회·단체 | B18: =COUNTIF(종합!$G$3:$G$501,"협회·단체") -> 11 | C18: =COUNTIFS(종합!$G$3:$G$501,"협회·단체",종합!$C$3:$C$501,"?*") -> 2 | D18: =COUNTIFS(종합!$G$3:$G$501,"협회·단체",종합!$D$3:$D$501,"?*") -> 3 | E18: =COUNTIFS(종합!$G$3:$G$501,"협회·단체",종합!$E$3:$E$501,"?*") -> 8 | F18: =COUNTIFS(종합!$G$3:$G$501,"협회·단체",종합!$F$3:$F$501,"?*") -> 1
A19: 합계 | B19: =SUM(B13:B18) -> 299 | C19: =SUM(C13:C18) -> 129 | D19: =SUM(D13:D18) -> 127 | E19: =SUM(E13:E18) -> 65 | F19: =SUM(F13:F18) -> 35
A20: 유형 미입력 | B20: =B4-B19 -> 0
A21: ※ 유형 확인 필요(추정 분류) | B21: =COUNTIF(종합!AA2:AA400,"*유형 확인*") -> 0
A23: 기업유형 분류 기준
A24: 대기업 | B24: 공정거래위원회 공시대상기업집단(자산총액 5조 원 이상, 2026.5.1 기준 102개 집단) 소속 회사. 상호출자제한기업집단(12조 원 이상) 포함. [출처: https://www.gnnnews.kr/167337]
A25: 중견기업 | B25: 「중견기업 성장촉진 및 경쟁력 강화에 관한 특별법」 제2조: 중소기업이 아니면서 상호출자제한기업집단·공공기관이 아닌 기업(공개 매출·자산 규모로 판정, 추정 시 ※). [출처: https://www.law.go.kr/LSW/lsInfoP.do?lsiSeq=195180]
A26: 중소기업 | B26: 「중소기업기본법」 시행령 별표1: 업종별 3년 평균매출액 400~1,500억 원 이하이고 자산총액 5천억 원 미만. 스타트업·벤처 포함. 위 기준에 해당하지 않는 영리법인은 기본값으로 중소기업 분류. [출처: https://www.mss.go.kr/site/smba/contents/view.do?menuCd=20103040000002024122824&siteCd=smba]
A27: 공공기관 | B27: 「공공기관의 운영에 관한 법률」 지정기관(공기업·준정부기관·기타공공기관, 정부출연연구기관 포함), 지자체 출연기관, 국가행정기관. [출처: https://www.law.go.kr/LSW/lsInfoP.do?lsId=010375&ancYnChk=0]
A28: 대학 | B28: 고등교육법상 대학 및 산학협력단.
A29: 협회·단체 | B29: 비영리 사단·재단법인, 협회·연합회·진흥원 등 회원제 단체(영리 주식회사 형태는 제외).

Sheet 종합
A1: 기업(기관) 정보 | O1: 활동 임원 | U1: 활동 실무 | AB1: [자동] 분과 시트 연동용 — 수정 금지
A2: No | B2: 회사(기관, 대학)명 | C2: 기술 | D2: 산업 | E2: 생태계 | F2: 안전·신뢰 | G2: 기업유형 | H2: 사업자등록번호 | I2: 대표자 | J2: 대표전화 | K2: 홈페이지 | L2: 이메일 주소 | M2: 주소 | N2: AI 전문 분야 및 보유기술·서비스(솔루션) | O2: 성명 | P2: 부서 | Q2: 직위/직책 | R2: 전화번호 | S2: 이메일 | T2: 휴대전화 번호 | U2: 성명 2 | V2: 부서 2 | W2: 직위/직책 2 | X2: 전화번호 2 | Y2: 이메일 2 | Z2: 휴대전화 번호 2 | AA2: 비고 | AB2: 기술 | AC2: 산업 | AD2: 생태계 | AE2: 안전·신뢰
A3: =IF(B3="","",ROW()-2) -> 1 | B3: 주식회사 케이솔루션즈 | D3: O | G3: 중소기업 | H3: 134-87-20969 | I3: 김민수 | J3: 02-6415-2236 | K3: https://www.ksolution.kr | L3: kangwoongkim@gmail.com | M3: 서울특별시 금천구 가산디지털1로 225, 418, 419호 | N3: Agentic AI MES, Agentic AI ERP, AI 기반 산업안전 솔루션 | O3: 김민수 | P3: - | Q3: 대표이사 | R3: - | S3: mskim@ksolution.kr | T3: 010-2236-3656 | U3: 김강웅 | V3: AX사업부 | W3: 이사 | X3: - | Y3: kwkim@ksolution.kr | Z3: 010-4526-3280 | AB3: =IF(LEN($C3)>0,COUNT(AB$1:AB2)+1,"") | AC3: =IF(LEN($D3)>0,COUNT(AC$1:AC2)+1,"") -> 1 | AD3: =IF(LEN($E3)>0,COUNT(AD$1:AD2)+1,"") | AE3: =IF(LEN($F3)>0,COUNT(AE$1:AE2)+1,"")
A4: =IF(B4="","",ROW()-2) -> 2 | B4: 농업회사법인 (주)온팜 | D4: O | G4: 중소기업 | H4: 291-88-01904 | I4: 정원기 | J4: 063-714-4977 | K4: beeonfarm.com | L4: magiclub72@gmail.com | M4: 전북 전주시 덕진구 오공로 43-32 대동빌딩 301호 | N4: 디지털 양봉 시스템/ GIS기반 전국 밀원분포 및 꿀벌 폐사위험 지도 | O4: 정원기 | P4: 대표 | Q4: 대표 | R4: 063-714-4977 | S4: onfarm@onfarm.co.kr | T4: 010-8760-9001 | U4: 김은환 | V4: 비온팜 | W4: 매니저 | X4: 063-714-4977 | Y4: before00@onfarm.co.kr | Z4: 010-5481-0716 | AA4: 2지망 생태계 신청 | AB4: =IF(LEN($C4)>0,COUNT(AB$1:AB3)+1,"") | AC4: =IF(LEN($D4)>0,COUNT(AC$1:AC3)+1,"") -> 2 | AD4: =IF(LEN($E4)>0,COUNT(AD$1:AD3)+1,"") | AE4: =IF(LEN($F4)>0,COUNT(AE$1:AE3)+1,"")
A5: =IF(B5="","",ROW()-2) -> 3 | B5: 에스큐케이 주식회사 | D5: O | G5: 중소기업 | H5: 316-87-02767 | I5: 손영제 | J5: 010-2989-1979 | K5: www.sqkcloud.com | L5: branki@gmail.com | M5: 서울시 강서구 마곡중앙8로 14 | N5: AI 모델 리파인먼트 & 파인튜닝 | O5: 손영제 | P5: 연구소 | Q5: 대표 | R5: 010-2989-1979 | S5: branki@sqkcloud.com | T5: 010-2989-1979 | U5: 손영제 | V5: 연구소 | W5: 대표 | X5: 010-2989-1979 | Y5: branki@sqkcloud.com | Z5: 010-2989-1979 | AB5: =IF(LEN($C5)>0,COUNT(AB$1:AB4)+1,"") | AC5: =IF(LEN($D5)>0,COUNT(AC$1:AC4)+1,"") -> 3 | AD5: =IF(LEN($E5)>0,COUNT(AD$1:AD4)+1,"") | AE5: =IF(LEN($F5)>0,COUNT(AE$1:AE4)+1,"")
A6: =IF(B6="","",ROW()-2) -> 4 | B6: 맨인블록 주식회사 | D6: O | G6: 중소기업 | H6: 731-86-02727 | I6: 박종형 | J6: 070-4012-1591 | K6: www.meninblox.com | L6: azuspark@gmail.com | M6: 광주광역시 북구 첨단과기로 339, 2층 214호 | N6: 의료, 헬스케어 | O6: 박종형 | P6: 개발실 | Q6: 대표이사 | R6: 070-4012-1591 | S6: benjamin@meninblox.com | T6: 010-2474-4797 | U6: 김은실 | V6: 경영젼략실 | W6: 이사 | X6: 070-4012-1591 | Y6: lucy@meninblox.com | Z6: 010-9371-4756 | AA6: 2지망 생태계 신청 | AB6: =IF(LEN($C6)>0,COUNT(AB$1:AB5)+1,"") | AC6: =IF(LEN($D6)>0,COUNT(AC$1:AC5)+1,"") -> 4 | AD6: =IF(LEN($E6)>0,COUNT(AD$1:AD5)+1,"") | AE6: =IF(LEN($F6)>0,COUNT(AE$1:AE5)+1,"")
A7: =IF(B7="","",ROW()-2) -> 5 | B7: 주식회사 에스에이티정보 | D7: O | G7: 중소기업 | H7: 119-86-26690 | I7: 오세용 | J7: 010-9005-5197 | K7: www.satu.co.kr | L7: a90055197@gmail.com | M7: 서울 구로구 디지털로 30길 28, 마리오타워 1401호 | N7: 문서 전처리(정제) 솔루션, 개인정보 비식별솔루션, RAG 플랫폼 등 | O7: 오세용 | P7: 경영 | Q7: 대표 | R7: 02-857-3051 | S7: ohsy@satu.co.kr | T7: 010-9005-5197 | U7: 오세용 | V7: 경영 | W7: 대표 | X7: 02-857-3051 | Y7: ohsy@satu.co.kr | Z7: 010-9005-5197 | AA7: 2지망 생태계 신청 | AB7: =IF(LEN($C7)>0,COUNT(AB$1:AB6)+1,"") | AC7: =IF(LEN($D7)>0,COUNT(AC$1:AC6)+1,"") -> 5 | AD7: =IF(LEN($E7)>0,COUNT(AD$1:AD6)+1,"") | AE7: =IF(LEN($F7)>0,COUNT(AE$1:AE6)+1,"")
A8: =IF(B8="","",ROW()-2) -> 6 | B8: 주식회사 씨에스리 | D8: O | G8: 중소기업 | H8: 105-87-86298 | I8: 이춘식 | J8: 02-307-0182 | K8: www.cslee.co.kr | L8: brightenhome@gmail.com | M8: 서울특별시 마포구 월드컵북로 396 누리꿈스퀘어 비즈니스타워 8층 | N8: 생성형 AI, 제조AI, RAG, CSMinwon, CSAufit, CSAIQ, CSBuzz | O8: 윤희우 | P8: AX사업부문 | Q8: 이사/부문장 | R8: 010-5645-9912 | S8: hwyoon@cslee.co.kr | T8: 010-5645-9912 | U8: 정두현 | V8: AIOps사업부 | W8: 기술이사/사업부장 | X8: 02-6356-4608 | Y8: chungpe@cslee.co.kr | Z8: 010-7362-6878 | AB8: =IF(LEN($C8)>0,COUNT(AB$1:AB7)+1,"") | AC8: =IF(LEN($D8)>0,COUNT(AC$1:AC7)+1,"") -> 6 | AD8: =IF(LEN($E8)>0,COUNT(AD$1:AD7)+1,"") | AE8: =IF(LEN($F8)>0,COUNT(AE$1:AE7)+1,"")
A9: =IF(B9="","",ROW()-2) -> 7 | B9: (주)사이냅소프트 | D9: O | E9: O | G9: 중소기업 | H9: 214-86-64984 | I9: 전경헌 | J9: 02-2039-3780 | K9: https://www.synapsoft.co.kr/ | L9: synapsoft@gmail.com | M9: 서울 강서구 마곡중앙4로 62 사이냅소프트 | N9: 사이냅 어시스턴트, 사이냅 도큐애널라이저 , 사이냅 OCR, 보이스애널라이저 등 | O9: 정진남 | P9: 공공영업팀 | Q9: 이사 | R9: 010-8759-7923 | S9: jjn0802@synapsoft.co.kr | T9: 010-8759-7923 | U9: 김윤서 | V9: 마케팅 | W9: 사원 | X9: 010-3012-9110 | Y9: rdyun25@synapsoft.co.kr | Z9: 010-3012-9110 | AB9: =IF(LEN($C9)>0,COUNT(AB$1:AB8)+1,"") | AC9: =IF(LEN($D9)>0,COUNT(AC$1:AC8)+1,"") -> 7 | AD9: =IF(LEN($E9)>0,COUNT(AD$1:AD8)+1,"") -> 1 | AE9: =IF(LEN($F9)>0,COUNT(AE$1:AE8)+1,"")
A10: =IF(B10="","",ROW()-2) -> 8 | B10: 주식회사 데이터누리 | D10: O | G10: 중소기업 | H10: 199-81-01308 | I10: 강태원 | J10: 02-6953-5313 | K10: www.datanuri.net | L10: naraerhee88@gmail.com | M10: 서울시 강서구 마곡중앙2로 39, 호디빌딩 3층 | N10: Metis DPP(Data Pipeline Platform) | O10: 강태원 | P10: - | Q10: 대표이사 | R10: 02-6953-5017 | S10: twkang@datanuri.net | T10: 010-2981-5084 | U10: 우형제 | V10: - | W10: 부사장 | X10: 02-6953-5413 | Y10: hjwoo@datanuri.net | Z10: 010-6400-5413 | AB10: =IF(LEN($C10)>0,COUNT(AB$1:AB9)+1,"") | AC10: =IF(LEN($D10)>0,COUNT(AC$1:AC9)+1,"") -> 8 | AD10: =IF(LEN($E10)>0,COUNT(AD$1:AD9)+1,"") | AE10: =IF(LEN($F10)>0,COUNT(AE$1:AE9)+1,"")
A11: =IF(B11="","",ROW()-2) -> 9 | B11: 주식회사 와탭랩스 | D11: O | G11: 중소기업 | H11: 851-88-00084 | I11: 이동인 | J11: 02-565-1803 | K11: https://whatap.io/ko | L11: yiseo@whatap.io | M11: 서울특별시 서초구 서초대로77길 17, 13층 1303호 | N11: 통합 Observability 서비스 | O11: 서영일 | P11: COO | Q11: COO | R11: 010-3255-6480 | S11: yiseo@whatap.io | T11: 010-3255-6480 | U11: 서영일 | V11: COO | W11: COO | X11: 010-3255-6480 | Y11: yiseo@whatap.io | Z11: 010-3255-6480 | AA11: 2지망 생태계 신청 | AB11: =IF(LEN($C11)>0,COUNT(AB$1:AB10)+1,"") | AC11: =IF(LEN($D11)>0,COUNT(AC$1:AC10)+1,"") -> 9 | AD11: =IF(LEN($E11)>0,COUNT(AD$1:AD10)+1,"") | AE11: =IF(LEN($F11)>0,COUNT(AE$1:AE10)+1,"")
A12: =IF(B12="","",ROW()-2) -> 10 | B12: 트래시스(주) | D12: O | G12: 중소기업 | H12: 538-88-01948 | I12: 양국승 | J12: 062-653-5555 | K12: www.trasys.net | L12: trasys21@gmail.com | M12: 광주광역시 북구 오룡동 1013 AICA 302호 | N12: 안전+지능(위험성평가), 리;본톡(트라우마상담) | O12: 양국승 | P12: 연구소 | Q12: 대표이사 | R12: 062-653-5555 | S12: trasys21@nate.com | T12: 010-8833-8019 | U12: 정재창 | V12: 연구소 | W12: 연구소장 | X12: 062-653-5555 | Y12: trasys21@nate.com | Z12: 010-9942-9247 | AB12: =IF(LEN($C12)>0,COUNT(AB$1:AB11)+1,"") | AC12: =IF(LEN($D12)>0,COUNT(AC$1:AC11)+1,"") -> 10 | AD12: =IF(LEN($E12)>0,COUNT(AD$1:AD11)+1,"") | AE12: =IF(LEN($F12)>0,COUNT(AE$1:AE11)+1,"")
A13: =IF(B13="","",ROW()-2) -> 11 | B13: 주식회사 케파스 | D13: O | G13: 중소기업 | H13: 105-87-39024 | I13: 주성돈 | J13: 010-3720-0580 | K13: www.kephas.kr | L13: ksksdjoo@gmail.com | M13: 강남구 논현로38길 16 | N13: FAROS-AI, FAROS-IOMS | O13: 주성돈 | P13: 경영 | Q13: 대표 | R13: 010-3720-0580 | S13: arnoldjoo@kephas.kr | T13: 010-3720-0580 | U13: 안광모 | V13: 부설연구소 | W13: 소장 | X13: 010-2439-2727 | Y13: gmahn@kephas.kr | Z13: 010-2439-2727 | AB13: =IF(LEN($C13)>0,COUNT(AB$1:AB12)+1,"") | AC13: =IF(LEN($D13)>0,COUNT(AC$1:AC12)+1,"") -> 11 | AD13: =IF(LEN($E13)>0,COUNT(AD$1:AD12)+1,"") | AE13: =IF(LEN($F13)>0,COUNT(AE$1:AE12)+1,"")
A14: =IF(B14="","",ROW()-2) -> 12 | B14: 주식회사 랭코드 | D14: O | G14: 중소기업 | H14: 567-81-01670 | I14: 김민준 | J14: 010-5511-4898 | K14: https://langcode.io/cxp | L14: marketjustice@gmail.com | M14: 서울특별시 서초구 서초대로50길 35, 8층 | N14: 기업용 AI 에이전트 플랫폼 및 통합 에이전트 허브 (랭코드 CXP) | O14: 김민준 | P14: C-Level | Q14: 대표이사 | R14: 010-5511-4898 | S14: admin@langcode.io | T14: 010-5511-4898 | U14: 손준희 | V14: 경영관리 | W14: 매니저 | X14: 010-9555-3581 | Y14: jhson@langcode.io | Z14: 010-9555-3581 | AB14: =IF(LEN($C14)>0,COUNT(AB$1:AB13)+1,"") | AC14: =IF(LEN($D14)>0,COUNT(AC$1:AC13)+1,"") -> 12 | AD14: =IF(LEN($E14)>0,COUNT(AD$1:AD13)+1,"") | AE14: =IF(LEN($F14)>0,COUNT(AE$1:AE13)+1,"")
A15: =IF(B15="","",ROW()-2) -> 13 | B15: 주식회사 베슬에이아이코리아 | D15: O | G15: 중소기업 | H15: 884-81-01731 | I15: 안재만 | J15: 010-2274-3161 | K15: https://vessl.ai | L15: jaden@vessl.ai | M15: 서울특별시 강남구 테헤란로5길 7, 13층(KG타워) | N15: GPUaaS/Orchstration 을 메인으로 하고, AI Agent Builder를 활용한 업무용 AI Agent를 엔터프라이즈 및 공공을 대상으로 병행함. | O15: 박준우 | P15: 사업부서 | Q15: 본부장 | R15: 010-9680-9607 | S15: jaden@vessl.ai | T15: 010-9680-9607 | U15: 박용규 | V15: 사업 | W15: 이사 | X15: 010-4095-3234 | Y15: mark@vessl.ai | Z15: 010-4095-3234 | AA15: 2지망 생태계 신청 | AB15: =IF(LEN($C15)>0,COUNT(AB$1:AB14)+1,"") | AC15: =IF(LEN($D15)>0,COUNT(AC$1:AC14)+1,"") -> 13 | AD15: =IF(LEN($E15)>0,COUNT(AD$1:AD14)+1,"") | AE15: =IF(LEN($F15)>0,COUNT(AE$1:AE14)+1,"")
A16: =IF(B16="","",ROW()-2) -> 14 | B16: (주)시즐 | D16: O | G16: 중소기업 | H16: 204-88-00482 | I16: 이지현 | J16: 032-458-5520 | K16: www.sizl.co.kr | L16: hanmanju88@gmail.com | M16: 인천광역시 연수구 갯벌로12, 미추홀타워 1804호 | N16: Agentic AI Brain | O16: 김현영 | P16: SDx 본부 | Q16: 부사장/본부장 | R16: 010-9044-4536 | S16: khy@sizl.co.kr | T16: 010-9044-4536 | U16: 한만주 | V16: 컨설팅팀 | W16: 과장/팀장 | X16: 010-7187-3416 | Y16: hmj@sizl.co.kr | Z16: 010-7187-3416 | AB16: =IF(LEN($C16)>0,COUNT(AB$1:AB15)+1,"") | AC16: =IF(LEN($D16)>0,COUNT(AC$1:AC15)+1,"") -> 14 | AD16: =IF(LEN($E16)>0,COUNT(AD$1:AD15)+1,"") | AE16: =IF(LEN($F16)>0,COUNT(AE$1:AE15)+1,"")
A17: =IF(B17="","",ROW()-2) -> 15 | B17: 주식회사 바이트사이즈 | D17: O | G17: 중소기업 | H17: 350-86-03129 | I17: 위영량 | J17: 051-717-0454 | K17: https://www.thebytesize.ai/ | L17: cleanupkorea@gmail.com | M17: 부산시 진구 엄광로 176 | N17: 신발·패션 제조산업을 중심으로 생성형 AI 및 Agentic AI 기반 디자인·품질·제조 업무 자동화 솔루션을 | O17: 위영량 | P17: 대표 | Q17: 대표 | R17: 051-717-0454 | S17: bytesize@thebytesize.co.kr | T17: 010-3069-5885 | U17: 정기철 | V17: 전략기획 | W17: 부장 | X17: 051-717-0454 | Y17: roy.jung@thebytesize.ai | Z17: 010-2205-9719 | AB17: =IF(LEN($C17)>0,COUNT(AB$1:AB16)+1,"") | AC17: =IF(LEN($D17)>0,COUNT(AC$1:AC16)+1,"") -> 15 | AD17: =IF(LEN($E17)>0,COUNT(AD$1:AD16)+1,"") | AE17: =IF(LEN($F17)>0,COUNT(AE$1:AE16)+1,"")
A18: =IF(B18="","",ROW()-2) -> 16 | B18: 주식회사 씨더스 농업회사법인 | D18: O | G18: 중소기업 | H18: 314-86-15920 | I18: 조성환 | J18: 042-710-4035 | K18: www.seeders.co.kr | L18: jhl9627@seeders.co.kr | M18: 대전시 중구 중앙로 118, 5층 | N18: AI 육종 시뮬레이션 플랫폼, AI 재배관리 에이전트 플랫폼 | O18: 조성환 | P18: 경영총괄 | Q18: CEO | R18: 010-6417-0614 | S18: shjo@seeders.co.kr | T18: 010-6417-0614 | U18: 정혜리 | V18: 경영 | W18: 부사장 | X18: 010-3484-9645 | Y18: jhl9627@seeders.co.kr | Z18: 010-3484-9645 | AB18: =IF(LEN($C18)>0,COUNT(AB$1:AB17)+1,"") | AC18: =IF(LEN($D18)>0,COUNT(AC$1:AC17)+1,"") -> 16 | AD18: =IF(LEN($E18)>0,COUNT(AD$1:AD17)+1,"") | AE18: =IF(LEN($F18)>0,COUNT(AE$1:AE17)+1,"")
A19: =IF(B19="","",ROW()-2) -> 17 | B19: (주)엘리스그룹 | D19: O | G19: 중소기업 | H19: 581-88-00303 | I19: 김재원 | J19: 1833-2677 | K19: https://elice.io/ko | L19: dahye.elice@gmail.com | M19: 서울시 강남구 선릉로 433, 신관 6 | N19: AI교육 플랫폼, AI솔루션, GPU 클라우드 등 | O19: 김수인 | P19: CRO디비전 | Q19: CRO(사내이사) | R19: 1833-2677 | S19: suin@elicer.com | T19: 010-5186-7109 | U19: 홍다혜 | V19: 공공사업AX팀 | W19: 팀장 | X19: 1833-2677 | Y19: dh@elicer.com | Z19: 010-9641-3299 | AB19: =IF(LEN($C19)>0,COUNT(AB$1:AB18)+1,"") | AC19: =IF(LEN($D19)>0,COUNT(AC$1:AC18)+1,"") -> 17 | AD19: =IF(LEN($E19)>0,COUNT(AD$1:AD18)+1,"") | AE19: =IF(LEN($F19)>0,COUNT(AE$1:AE18)+1,"")
A20: =IF(B20="","",ROW()-2) -> 18 | B20: (주)데이터사이언스랩 | D20: O | G20: 중소기업 | H20: 274-87-00470 | I20: 유희경 | J20: 02-565-1123 | K20: www.dataslab.co.kr | L20: gis.hkyoo@gmail.com | M20: 서울시 송파구 법원로 8길 8, 문정역2차 SK V1 604호 | N20: Agentic Datascientist (분석가 에이전트), ToR-RAG | O20: 유희경 | P20: 경영 | Q20: 대표이사 | R20: 010-4424-4479 | S20: hkyoo@dataslab.co.kr | T20: 010-4424-4479 | U20: 김원배 | V20: 기업부설연구소 | W20: 연구소장 | X20: 02-565-1123 | Y20: wonkim@dataslab.co.kr | Z20: 010-3400-4527 | AB20: =IF(LEN($C20)>0,COUNT(AB$1:AB19)+1,"") | AC20: =IF(LEN($D20)>0,COUNT(AC$1:AC19)+1,"") -> 18 | AD20: =IF(LEN($E20)>0,COUNT(AD$1:AD19)+1,"") | AE20: =IF(LEN($F20)>0,COUNT(AE$1:AE19)+1,"")
A21: =IF(B21="","",ROW()-2) -> 19 | B21: (주)미소정보기술 | D21: O | G21: 중소기업 | H21: 220-87-25270 | I21: 남상도 | J21: 02-2205-0551 | K21: www.misoinfo.co.kr | L21: jaeminet@gmail.com | M21: 경기도 과천시 과천대로 12길 117, 과천펜타원 G동 1402호 | N21: SmartBIG, Daxi, SmartTA, SmartMDQ(조달혁신제품) Ai멀티모달데이터플랫폼 외 | O21: 박준욱 | P21: 강원지사 | Q21: 지사장/ 상무이사 | R21: 033-764-0553 | S21: tony@misoinfo.co.kr | T21: 010-7731-7367 | U21: 김성우 | V21: 강원지사 | W21: 팀장(공학박사)/ 부장 | X21: 033-764-0553 | Y21: kimsw0912@misoinfo.co.kr | Z21: 010-8436-2772 | AA21: 2지망 생태계 신청 | AB21: =IF(LEN($C21)>0,COUNT(AB$1:AB20)+1,"") | AC21: =IF(LEN($D21)>0,COUNT(AC$1:AC20)+1,"") -> 19 | AD21: =IF(LEN($E21)>0,COUNT(AD$1:AD20)+1,"") | AE21: =IF(LEN($F21)>0,COUNT(AE$1:AE20)+1,"")
A22: =IF(B22="","",ROW()-2) -> 20 | B22: (주)비아이매트릭스 | D22: O | G22: 중소기업 | H22: 120-86-79936 | I22: 배영근 | J22: 02-561-4475 | K22: www.bimatrix.co.kr | L22: bimatrixkorea@gmail.com | M22: 서울 강남구 선릉로 433 (역삼동) 세방빌딩 신관 17층 | N22: 온톨로지 기반 Agentic AI 개발 플랫폼 TRINITY/말로 하는 DB 데이터 분석 AI 솔루션 G-MATRIX/업무시스템 구축 AI 솔루션 AUD플랫폼 | O22: 배영근 | P22: 대표이사 | Q22: 대표이사 | R22: 02-561-4475 | S22: bae@bimatrix.co.kr | T22: 010-9132-4361 | U22: 정해선 | V22: 마테팅 | W22: 차장 | X22: 070-4338-5415 | Y22: mktg@bimatrix.co.kr | Z22: 010-9959-9529 | AB22: =IF(LEN($C22)>0,COUNT(AB$1:AB21)+1,"") | AC22: =IF(LEN($D22)>0,COUNT(AC$1:AC21)+1,"") -> 20 | AD22: =IF(LEN($E22)>0,COUNT(AD$1:AD21)+1,"") | AE22: =IF(LEN($F22)>0,COUNT(AE$1:AE21)+1,"")
A23: =IF(B23="","",ROW()-2) -> 21 | B23: 국제드론표준산업협회 Ko-Biz Alliance Co.,LTD | D23: O | G23: 협회·단체 | H23: 619-82-62882 | I23: 박종민 | J23: 010-9279-3437 | K23: www.idsia.co.kr | L23: idssaceo@gmail.com | M23: 경기도 김포시 김포한강2로72번길10, 113호(라베니체) | N23: ICT국제표준전문가, ICT기술표준자문전문가, 한국드론시스템 국가표준위원, 피지컬AI드론기술시스템(AI민군드론통합시스템 : 물류배송, 농업, 감시정찰, 인스팩션, 드론항공안전 등) | O23: 박종민 | P23: ICT국제표준화본부 | Q23: 대표/대표 | R23: 010-9279-3437 | S23: dronesquare@naver.com | T23: 010-9279-3437 | U23: 김용진 | V23: ICT국제표준화본부 | W23: 이사/부회장 | X23: 010-5074-2224 | Y23: kim292224@naver.com | Z23: 010-5074-2224 | AA23: 2지망 생태계 신청 | AB23: =IF(LEN($C23)>0,COUNT(AB$1:AB22)+1,"") | AC23: =IF(LEN($D23)>0,COUNT(AC$1:AC22)+1,"") -> 21 | AD23: =IF(LEN($E23)>0,COUNT(AD$1:AD22)+1,"") | AE23: =IF(LEN($F23)>0,COUNT(AE$1:AE22)+1,"")
A24: =IF(B24="","",ROW()-2) -> 22 | B24: 주식회사 비에이치에스엔 | D24: O | G24: 중소기업 | H24: 266-87-01764 | I24: 임정근 | J24: 02-521-2999 | K24: https://bhsn.ai/ | L24: hjjeon@bhsn.ai | M24: 서울특별시 강남구 삼성로 570, 5층 (06163) | N24: 리걸 특화 LLM 및 에이전트(법령, 판례 검색 및 업무 자동화 서비스) | O24: 임정근 | P24: CEO | Q24: CEO | R24: 02-521-2999 | S24: jklim@bhsn.ai | T24: 010-9153-5280 | U24: 전혜주 | V24: 비즈니스팀 | W24: PM | X24: 010-8525-7309 | Y24: hjjeon@bhsn.ai | Z24: 010-8525-7309 | AA24: 2지망 생태계 신청 | AB24: =IF(LEN($C24)>0,COUNT(AB$1:AB23)+1,"") | AC24: =IF(LEN($D24)>0,COUNT(AC$1:AC23)+1,"") -> 22 | AD24: =IF(LEN($E24)>0,COUNT(AD$1:AD23)+1,"") | AE24: =IF(LEN($F24)>0,COUNT(AE$1:AE23)+1,"")
A25: =IF(B25="","",ROW()-2) -> 23 | B25: 주식회사 데이원컴퍼니 | D25: O | G25: 중소기업 | H25: 810-86-00658 | I25: 이강민 | J25: 010-9158-5979 | K25: https://day1company.co.kr/ | L25: sunyoung.chae@day1company.co.kr | M25: 서울 강남구 테헤란로 231, 센터필드 WEST 6~7층 | N25: AI기반 교육서비스 / 스킬플로(자연어검색, 개인맞춤형 큐레이션), 스킬매치(AI직무스킬진단), AI튜터(온라인AI강사), | O25: 신해동 | P25: 패스트캠퍼스 | Q25: 대표 | R25: 010-8875-5896 | S25: haedong@day1company.co.kr | T25: 010-8875-5896 | U25: 김지훈 | V25: B2G부문 | W25: 부문대표 | X25: 010-9064-8413 | Y25: jhkim@day1company.co.kr | Z25: 010-9064-8413 | AA25: 2지망 생태계 신청 | AB25: =IF(LEN($C25)>0,COUNT(AB$1:AB24)+1,"") | AC25: =IF(LEN($D25)>0,COUNT(AC$1:AC24)+1,"") -> 23 | AD25: =IF(LEN($E25)>0,COUNT(AD$1:AD24)+1,"") | AE25: =IF(LEN($F25)>0,COUNT(AE$1:AE24)+1,"")
A26: =IF(B26="","",ROW()-2) -> 24 | B26: ㈜이큐포올 | D26: O | G26: 중소기업 | H26: 161-81-00885 | I26: 이인구 | J26: 02-6207-7897 | K26: https://www.eq4all.co.kr/ | L26: edenlee@eq4all.co.kr | M26: 서울특별시 강남구 논현로76길 11, 4층(역삼동, 코람벤처빌딩) | N26: 정보 접근성 (수어/쉬운 정보), 3D 수어 아바타 번역 기술, 쉬운 정보 변환 기술 | O26: 이인구 | P26: (공란) | Q26: 대표 | R26: 02-6207-7897 | S26: kevinlee@eq4all.co.kr | T26: 010-4227-3841 | U26: 주소현 | V26: 이사 | W26: 마케팅실 | X26: 02-6207-7897 | Y26: josephinejoo@eq4all.co.kr | Z26: 010-3490-6723 | AA26: 2지망 생태계 신청 | AB26: =IF(LEN($C26)>0,COUNT(AB$1:AB25)+1,"") | AC26: =IF(LEN($D26)>0,COUNT(AC$1:AC25)+1,"") -> 24 | AD26: =IF(LEN($E26)>0,COUNT(AD$1:AD25)+1,"") | AE26: =IF(LEN($F26)>0,COUNT(AE$1:AE25)+1,"")
A27: =IF(B27="","",ROW()-2) -> 25 | B27: (주)오픈네트웍시스템 | D27: O | G27: 중소기업 | H27: 107-81-69444 | I27: 박봉균 | J27: 1544-0357 | K27: https://open-network.co.kr/ | L27: parksujin0906@gmail.com | M27: 경기도 의왕시 이미로 40, B동 907호 인덕원 IT밸리 | N27: LLMOps 플랫폼 및 ONS AX Foundry 서비스 | O27: 박종일 | P27: S/W 개발부 | Q27: 매니저 | R27: 010-5348-5208 | S27: jongpark@open-network.co.kr | T27: 010-5348-5208 | U27: 박수진 | V27: 영업부 | W27: 매니저 | X27: 010-8817-5208 | Y27: sujin@open-network.co.kr | Z27: 010-8817-5208 | AB27: =IF(LEN($C27)>0,COUNT(AB$1:AB26)+1,"") | AC27: =IF(LEN($D27)>0,COUNT(AC$1:AC26)+1,"") -> 25 | AD27: =IF(LEN($E27)>0,COUNT(AD$1:AD26)+1,"") | AE27: =IF(LEN($F27)>0,COUNT(AE$1:AE26)+1,"")
A28: =IF(B28="","",ROW()-2) -> 26 | B28: 바운드포 주식회사 | D28: O | G28: 중소기업 | H28: 617-87-01415 | I28: 황인호 | J28: 010-9996-2707 | K28: www.bound4.co.kr | L28: inhovation@bound4.co.kr | M28: 서울시 강남구 언주로 617 3층 | N28: 드로파이(DROPAI) - GPDataOps | O28: 황인호 | P28: 경영전략팀 | Q28: 대표이사 | R28: 010-9996-2707 | S28: inhovation@bound4.co.kr | T28: 010-9996-2707 | U28: 황인호 | V28: 경영전략팀 | W28: 대표이사 | X28: 010-9996-2707 | Y28: inhovation@bound4.co.kr | Z28: 010-9996-2707 | AB28: =IF(LEN($C28)>0,COUNT(AB$1:AB27)+1,"") | AC28: =IF(LEN($D28)>0,COUNT(AC$1:AC27)+1,"") -> 26 | AD28: =IF(LEN($E28)>0,COUNT(AD$1:AD27)+1,"") | AE28: =IF(LEN($F28)>0,COUNT(AE$1:AE27)+1,"")
A29: =IF(B29="","",ROW()-2) -> 27 | B29: 럽디(주) | D29: O | G29: 중소기업 | H29: 651-81-00409 | I29: 김나라 | J29: 02-752-0719 | K29: https://luvd.co.kr | L29: geoluck0725@gmail.com | M29: 서울 관악구 남부순환로 1698 | N29: AEO(Answer Engine Optimization)/ 및 GEO를 위한 분석/실행 기술 | O29: 이장원 | P29: 기업부설연구소 | Q29: 상무/CTO | R29: 010-9501-8096 | S29: jwlee@luvd.co.kr | T29: 010-9501-8096 | U29: 이장원 | V29: 기업부설연구소 | W29: 상무/CTO | X29: 010-9501-8096 | Y29: jwlee@luvd.co.kr | Z29: 010-9501-8096 | AB29: =IF(LEN($C29)>0,COUNT(AB$1:AB28)+1,"") | AC29: =IF(LEN($D29)>0,COUNT(AC$1:AC28)+1,"") -> 27 | AD29: =IF(LEN($E29)>0,COUNT(AD$1:AD28)+1,"") | AE29: =IF(LEN($F29)>0,COUNT(AE$1:AE28)+1,"")
A30: =IF(B30="","",ROW()-2) -> 28 | B30: (주)가온아이 | D30: O | G30: 중소기업 | H30: 211-86-97088 | I30: 조창제 | J30: 02-2140-5700 | K30: https://www.kaoni.com | L30: mjang3030@gmail.com | M30: 경기도 과천시 과천대로 12길 117 과천펜타원 D동 1~4층, 10~15층 | N30: KAON AI(일반 기업 협업 Agent, 기록관리 Agent, CCTV관제 및 안전 Agent) | O30: 조창제 | P30: - | Q30: 대표이사 | R30: 02-2140-5700 | S30: cjcho@kaoni.com | T30: 010-2546-9499 | U30: 전일권 | V30: 지식관리연구소 | W30: 전무/소장 | X30: 02-2140-5729 | Y30: ikjun@kaoni.com | Z30: 010-9166-3636 | AA30: 2지망 생태계 신청 | AB30: =IF(LEN($C30)>0,COUNT(AB$1:AB29)+1,"") | AC30: =IF(LEN($D30)>0,COUNT(AC$1:AC29)+1,"") -> 28 | AD30: =IF(LEN($E30)>0,COUNT(AD$1:AD29)+1,"") | AE30: =IF(LEN($F30)>0,COUNT(AE$1:AE29)+1,"")
A31: =IF(B31="","",ROW()-2) -> 29 | B31: 코코넛사일로 주식회사 | D31: O | G31: 중소기업 | H31: 677-88-01506 | I31: 김승용 | J31: 02-564-0309 | K31: https://www.coconutsilo.com | L31: hr@coconutsilo.com | M31: 서울특별시 구로구 디지털로31길 62, 제1712-1715호(구로동, 아티스포럼) | N31: AI 기반 SW 물류 포워딩 플랫폼 | O31: 김승용 | P31: CEO실 | Q31: 대표이사 | R31: 02-564-0309 | S31: seungyong@coconutsilo.com | T31: 010-2334-9342 | U31: 권성일 | V31: CTO실 | W31: 이사 | X31: 02-564-0309 | Y31: samuel@coconutsilo.com | Z31: 010-5544-8108 | AA31: 2지망 생태계 신청 | AB31: =IF(LEN($C31)>0,COUNT(AB$1:AB30)+1,"") | AC31: =IF(LEN($D31)>0,COUNT(AC$1:AC30)+1,"") -> 29 | AD31: =IF(LEN($E31)>0,COUNT(AD$1:AD30)+1,"") | AE31: =IF(LEN($F31)>0,COUNT(AE$1:AE30)+1,"")
A32: =IF(B32="","",ROW()-2) -> 30 | B32: 주식회사 아이티센클로잇 | D32: O | G32: 중견기업 | H32: 116-81-33315 | I32: 김우성 | J32: 010-7522-0966 | K32: https://itcencloit.com/ | L32: bschang@itcen.com | M32: 경기도 과천시 과천대로 12길 117, 과천펜타원 E동 (아이티센타워) | N32: AI 자체 솔루션(Agentic AI 플랫폼) 및 AI 기술 표준 (AgentGo) | O32: 이규진 | P32: AX사업본부 | Q32: 전무 / 본부장 | R32: 010-3664-6546 | S32: kjlee@itcen.com | T32: 010-3664-6546 | U32: 신기호 | V32: AX사업부 | W32: 상무 / 사업부장 | X32: 010-3509-7466 | Y32: ghshin@itcen.com | Z32: 010-3509-7466 | AA32: 2지망 생태계 신청 | AB32: =IF(LEN($C32)>0,COUNT(AB$1:AB31)+1,"") | AC32: =IF(LEN($D32)>0,COUNT(AC$1:AC31)+1,"") -> 30 | AD32: =IF(LEN($E32)>0,COUNT(AD$1:AD31)+1,"") | AE32: =IF(LEN($F32)>0,COUNT(AE$1:AE31)+1,"")
A33: =IF(B33="","",ROW()-2) -> 31 | B33: 주식회사 에이테크 | D33: O | G33: 중소기업 | H33: 685-86-00969 | I33: 김정완 | J33: 010-9591-3114 | K33: https://atech1221.com/ | L33: kikong1414@gmail.com | M33: 울산광역시 중구 종가로 655 혁신센트럴시티 307호 | N33: 제조 AI 통합 운영 관리 솔루션, AI Agent 기반 사무 자동화 지원 솔루션, 제조 데이터 기반 제조 KPI AI 예측 솔루션, 피지컬 AI 기반 로봇암 품질 개선 자동화 지원 솔루션 | O33: 서보경 | P33: 사업제안팀 | Q33: 수석/팀장 | R33: 010-3908-8301 | S33: sbgalex@atech1221.com | T33: 010-3908-8301 | U33: 권기광 | V33: AI 개발팀 | W33: 책임/팀장 | X33: 010-8807-0689 | Y33: kk.kwon@atech1221.com | Z33: 010-8807-0689 | AA33: 2지망 생태계 신청 | AB33: =IF(LEN($C33)>0,COUNT(AB$1:AB32)+1,"") | AC33: =IF(LEN($D33)>0,COUNT(AC$1:AC32)+1,"") -> 31 | AD33: =IF(LEN($E33)>0,COUNT(AD$1:AD32)+1,"") | AE33: =IF(LEN($F33)>0,COUNT(AE$1:AE32)+1,"")
A34: =IF(B34="","",ROW()-2) -> 32 | B34: 앵글컴퍼니 주식회사 | C34: O | D34: O | E34: O | G34: 중소기업 | H34: 172-88-02621 | I34: 박재범 | J34: 010-4717-8478 | K34: https://www.angle.im | L34: pjb@angle.im | M34: 서울시 강남구 테헤란로 79길 6, 3층 | N34: 헬스케어, 보험, 커머스, 제조 분야의 에이전틱 AI 에이전트 솔루션 | O34: 박재범 | P34: 대표이사 | Q34: 대표이사 | R34: 010-4717-8478 | S34: pjb@angle.im | T34: 010-4717-8478 | U34: 박재범 | V34: 대표이사 | W34: 대표이사 | X34: 010-4717-8478 | Y34: pjb@angle.im | Z34: 010-4717-8478 | AB34: =IF(LEN($C34)>0,COUNT(AB$1:AB33)+1,"") -> 1 | AC34: =IF(LEN($D34)>0,COUNT(AC$1:AC33)+1,"") -> 32 | AD34: =IF(LEN($E34)>0,COUNT(AD$1:AD33)+1,"") -> 2 | AE34: =IF(LEN($F34)>0,COUNT(AE$1:AE33)+1,"")
A35: =IF(B35="","",ROW()-2) -> 33 | B35: (주)컴퓨터메이트 | D35: O | G35: 중소기업 | H35: 515-81-31630 | I35: 서상인,김성호 | J35: 053-813-3008 | K35: https://www.computermate.co.kr/kor | L35: yuhyun.kim65@gmail.com | M35: 대구시 수성구 알파시티1로 35길 23 (대흥동) | N35: 제조분야 AI 솔루션(ADUP(이상탐지범용플랫폼) AD(설비이상탐지) QP(품질예측) OPC(최적공정조건)) TMS(시험관리시스템) CPS(가상물리시스템) | O35: 김유현 | P35: 부사장 | Q35: 부사장 | R35: 053-813-3008 | S35: yuhyun@computermate.co.kr | T35: 010-2253-4115 | U35: 김유현 | V35: 부사장 | W35: 부사장 | X35: 053-813-3008 | Y35: yuhyun@computermate.co.kr | Z35: 010-2253-4115 | AB35: =IF(LEN($C35)>0,COUNT(AB$1:AB34)+1,"") | AC35: =IF(LEN($D35)>0,COUNT(AC$1:AC34)+1,"") -> 33 | AD35: =IF(LEN($E35)>0,COUNT(AD$1:AD34)+1,"") | AE35: =IF(LEN($F35)>0,COUNT(AE$1:AE34)+1,"")
A36: =IF(B36="","",ROW()-2) -> 34 | B36: 사단법인 한국인공지능클라우드산업협회 | D36: O | G36: 협회·단체 | H36: 214-82-11607 | I36: 최지웅 | J36: 02-6354-0423 | K36: https://kcloud.or.kr | L36: skawn83@gmail.com | M36: 서울시 서초구 서초대로4길 4, 대진빌딩 2층, 3층 | N36: AI 클라우드 산업 지원 등 | O36: 함재춘 | P36: 사무국 | Q36: 사무국장 | R36: 02-6354-0422 | S36: jcham@kcloud.or.kr | T36: 010-3392-0043 | U36: 김남주 | V36: 클라우드융합팀 | W36: 수석팀장 | X36: 02-6354-0423 | Y36: skawn83@kcloud.or.kr | Z36: 010-8804-4324 | AB36: =IF(LEN($C36)>0,COUNT(AB$1:AB35)+1,"") | AC36: =IF(LEN($D36)>0,COUNT(AC$1:AC35)+1,"") -> 34 | AD36: =IF(LEN($E36)>0,COUNT(AD$1:AD35)+1,"") | AE36: =IF(LEN($F36)>0,COUNT(AE$1:AE35)+1,"")
A37: =IF(B37="","",ROW()-2) -> 35 | B37: 인프라닉스 주식회사 | D37: O | G37: 중소기업 | H37: 220-81-92632 | I37: 송 영 선 | J37: 02-598-3223 | K37: www.infranics.com | L37: young.song@infranicsmail.com | M37: 서울시 서초구 서추중앙로 66 서초빌딩 3층,5층 | N37: SysMaster Suite AI Manager/PHM,EO,PCF | O37: 송영선 | P37: 임원실 | Q37: 대표 | R37: 02-598-3223 | S37: young.song@infranicsmail.com | T37: 010-5330-9905 | U37: 심재승 | V37: 기술연구소/AI사업부 | W37: 부사장 | X37: 02-598-3223 | Y37: jae.shim@infranicsmail.com | Z37: 010-8871-7702 | AA37: 2지망 생태계 신청 | AB37: =IF(LEN($C37)>0,COUNT(AB$1:AB36)+1,"") | AC37: =IF(LEN($D37)>0,COUNT(AC$1:AC36)+1,"") -> 35 | AD37: =IF(LEN($E37)>0,COUNT(AD$1:AD36)+1,"") | AE37: =IF(LEN($F37)>0,COUNT(AE$1:AE36)+1,"")
A38: =IF(B38="","",ROW()-2) -> 36 | B38: (주)소울인포테크 | D38: O | G38: 중소기업 | H38: 123-86-18919 | I38: 황철연 | J38: 070-4280-4422 | K38: www.soulinfotech.com | L38: innsup@gmail.com | M38: 경기도 안양시 동안구 엘에스로116번길 25-32, 520호 | N38: 교통부문 시뮬레이션 및 AI 데이터 분석 | O38: 신인섭 | P38: 기업부설연구소 | Q38: 상무/연구소장 | R38: 070-4280-4422 | S38: innsup@soulint.com | T38: 010-8915-5829 | U38: 김영광 | V38: 기업부설연구소 | W38: 과장/연구원 | X38: 070-4280-4422 | Y38: kimyk@soulint.com | Z38: 010-5040-3389 | AA38: 2지망 생태계 신청 | AB38: =IF(LEN($C38)>0,COUNT(AB$1:AB37)+1,"") | AC38: =IF(LEN($D38)>0,COUNT(AC$1:AC37)+1,"") -> 36 | AD38: =IF(LEN($E38)>0,COUNT(AD$1:AD37)+1,"") | AE38: =IF(LEN($F38)>0,COUNT(AE$1:AE37)+1,"")
A39: =IF(B39="","",ROW()-2) -> 37 | B39: (주)제이에스시스템 | D39: O | G39: 중소기업 | H39: 503-81-66460 | I39: 이상도 | J39: 053-943-0154 | K39: http://js-system.co.kr/ | L39: leoyh23@gmail.com | M39: 대구광역시 수성구 알파시티1로 31길 39(대흥동, JSS빌딩) | N39: 제조 AI: 1. 생산관리/지시 최적화 솔루션; 2. 제조 LLM; 3. 설비고장예측 솔루션; 4. 통합품질관리솔루션 | O39: 이문용 | P39: 기획관리 | Q39: 상무 | R39: 053-943-0154 | S39: my@js-system.co.kr | T39: 010-6575-9686 | U39: 주리오 | V39: 기획관리 | W39: 과장/ 경기지사장 | X39: 053-943-0154 | Y39: leo@js-system.co.kr | Z39: 010-6313-9303 | AA39: 2지망 생태계 신청 | AB39: =IF(LEN($C39)>0,COUNT(AB$1:AB38)+1,"") | AC39: =IF(LEN($D39)>0,COUNT(AC$1:AC38)+1,"") -> 37 | AD39: =IF(LEN($E39)>0,COUNT(AD$1:AD38)+1,"") | AE39: =IF(LEN($F39)>0,COUNT(AE$1:AE38)+1,"")
A40: =IF(B40="","",ROW()-2) -> 38 | B40: 주식회사 인사이트온 | D40: O | G40: 중소기업 | H40: 522-88-00100 | I40: 박승래 | J40: 010-8686-5188 | K40: insighton.co.kr | L40: sr.victor.park@gmail.com | M40: 울산 중구 종가5길 21 | N40: Thingsflow(Low Code) & Neuroflow(Agentic AI) | O40: 박승래 | P40: 대표 | Q40: 대표 | R40: 010-8686-5188 | S40: victor.park@insighton.kr | T40: 010-8686-5188 | U40: 성령재 | V40: 연구소 | W40: 이사 | X40: 010-4520-3331 | Y40: rjseong@insighton.kr | Z40: 010-4520-3331 | AB40: =IF(LEN($C40)>0,COUNT(AB$1:AB39)+1,"") | AC40: =IF(LEN($D40)>0,COUNT(AC$1:AC39)+1,"") -> 38 | AD40: =IF(LEN($E40)>0,COUNT(AD$1:AD39)+1,"") | AE40: =IF(LEN($F40)>0,COUNT(AE$1:AE39)+1,"")
...

Sheet 기술분과
A1: 기업(기관) 정보 | O1: 활동 임원 | U1: 활동 실무
A2: No | B2: 회사(기관, 대학)명 | C2: 기술 | D2: 산업 | E2: 생태계 | F2: 안전·신뢰 | G2: 기업유형 | H2: 사업자등록번호 | I2: 대표자 | J2: 대표전화 | K2: 홈페이지 | L2: 이메일 주소 | M2: 주소 | N2: AI 전문 분야 및 보유기술·서비스(솔루션) | O2: 성명 | P2: 부서 | Q2: 직위/직책 | R2: 전화번호 | S2: 이메일 | T2: 휴대전화 번호 | U2: 성명 2 | V2: 부서 2 | W2: 직위/직책 2 | X2: 전화번호 2 | Y2: 이메일 2 | Z2: 휴대전화 번호 2
A3: =IF(B3="","",ROW()-2) -> 1 | B3: =IFERROR(INDEX(종합!B$3:B$501,MATCH(ROW()-2,종합!$AB$3:$AB$501,0))&"","") -> 앵글컴퍼니 주식회사 | C3: =IFERROR(INDEX(종합!C$3:C$501,MATCH(ROW()-2,종합!$AB$3:$AB$501,0))&"","") -> O | D3: =IFERROR(INDEX(종합!D$3:D$501,MATCH(ROW()-2,종합!$AB$3:$AB$501,0))&"","") -> O | E3: =IFERROR(INDEX(종합!E$3:E$501,MATCH(ROW()-2,종합!$AB$3:$AB$501,0))&"","") -> O | F3: =IFERROR(INDEX(종합!F$3:F$501,MATCH(ROW()-2,종합!$AB$3:$AB$501,0))&"","") | G3: =IFERROR(INDEX(종합!G$3:G$501,MATCH(ROW()-2,종합!$AB$3:$AB$501,0))&"","") -> 중소기업 | H3: =IFERROR(INDEX(종합!H$3:H$501,MATCH(ROW()-2,종합!$AB$3:$AB$501,0))&"","") -> 172-88-02621 | I3: =IFERROR(INDEX(종합!I$3:I$501,MATCH(ROW()-2,종합!$AB$3:$AB$501,0))&"","") -> 박재범 | ... Z3: =IFERROR(INDEX(종합!Z$3:Z$501,MATCH(ROW()-2,종합!$AB$3:$AB$501,0))&"","") -> 010-4717-8478
A4: =IF(B4="","",ROW()-2) -> 2 | B4: =IFERROR(INDEX(종합!B$3:B$501,MATCH(ROW()-2,종합!$AB$3:$AB$501,0))&"","") -> (주)글로비트 | C4: =IFERROR(INDEX(종합!C$3:C$501,MATCH(ROW()-2,종합!$AB$3:$AB$501,0))&"","") -> O | D4: =IFERROR(INDEX(종합!D$3:D$501,MATCH(ROW()-2,종합!$AB$3:$AB$501,0))&"","") -> O | E4: =IFERROR(INDEX(종합!E$3:E$501,MATCH(ROW()-2,종합!$AB$3:$AB$501,0))&"","") | F4: =IFERROR(INDEX(종합!F$3:F$501,MATCH(ROW()-2,종합!$AB$3:$AB$501,0))&"","") | G4: =IFERROR(INDEX(종합!G$3:G$501,MATCH(ROW()-2,종합!$AB$3:$AB$501,0))&"","") -> 중소기업 | H4: =IFERROR(INDEX(종합!H$3:H$501,MATCH(ROW()-2,종합!$AB$3:$AB$501,0))&"","") -> 616-81-92018 | I4: =IFERROR(INDEX(종합!I$3:I$501,MATCH(ROW()-2,종합!$AB$3:$AB$501,0))&"","") -> 김형수 | ... Z4: =IFERROR(INDEX(종합!Z$3:Z$501,MATCH(ROW()-2,종합!$AB$3:$AB$501,0))&"","") -> 010-2981-6386
A5: =IF(B5="","",ROW()-2) -> 3 | B5: =IFERROR(INDEX(종합!B$3:B$501,MATCH(ROW()-2,종합!$AB$3:$AB$501,0))&"","") -> 주식회사 시넥스 | C5: =IFERROR(INDEX(종합!C$3:C$501,MATCH(ROW()-2,종합!$AB$3:$AB$501,0))&"","") -> O | D5: =IFERROR(INDEX(종합!D$3:D$501,MATCH(ROW()-2,종합!$AB$3:$AB$501,0))&"","") -> O | E5: =IFERROR(INDEX(종합!E$3:E$501,MATCH(ROW()-2,종합!$AB$3:$AB$501,0))&"","") -> O | F5: =IFERROR(INDEX(종합!F$3:F$501,MATCH(ROW()-2,종합!$AB$3:$AB$501,0))&"","") | G5: =IFERROR(INDEX(종합!G$3:G$501,MATCH(ROW()-2,종합!$AB$3:$AB$501,0))&"","") -> 중소기업 | H5: =IFERROR(INDEX(종합!H$3:H$501,MATCH(ROW()-2,종합!$AB$3:$AB$501,0))&"","") -> 744-87-03807 | I5: =IFERROR(INDEX(종합!I$3:I$501,MATCH(ROW()-2,종합!$AB$3:$AB$501,0))&"","") -> 이대은 | ... Z5: =IFERROR(INDEX(종합!Z$3:Z$501,MATCH(ROW()-2,종합!$AB$3:$AB$501,0))&"","") -> 010-2450-0854
A6: =IF(B6="","",ROW()-2) -> 4 | B6: =IFERROR(INDEX(종합!B$3:B$501,MATCH(ROW()-2,종합!$AB$3:$AB$501,0))&"","") -> (주)디토닉 | C6: =IFERROR(INDEX(종합!C$3:C$501,MATCH(ROW()-2,종합!$AB$3:$AB$501,0))&"","") -> O | D6: =IFERROR(INDEX(종합!D$3:D$501,MATCH(ROW()-2,종합!$AB$3:$AB$501,0))&"","") -> O | E6: =IFERROR(INDEX(종합!E$3:E$501,MATCH(ROW()-2,종합!$AB$3:$AB$501,0))&"","") | F6: =IFERROR(INDEX(종합!F$3:F$501,MATCH(ROW()-2,종합!$AB$3:$AB$501,0))&"","") | G6: =IFERROR(INDEX(종합!G$3:G$501,MATCH(ROW()-2,종합!$AB$3:$AB$501,0))&"","") -> 중소기업 | H6: =IFERROR(INDEX(종합!H$3:H$501,MATCH(ROW()-2,종합!$AB$3:$AB$501,0))&"","") -> 264-81-37380 | I6: =IFERROR(INDEX(종합!I$3:I$501,MATCH(ROW()-2,종합!$AB$3:$AB$501,0))&"","") -> 전용주 | ... Z6: =IFERROR(INDEX(종합!Z$3:Z$501,MATCH(ROW()-2,종합!$AB$3:$AB$501,0))&"","") -> 010-8990-6844
A7: =IF(B7="","",ROW()-2) -> 5 | B7: =IFERROR(INDEX(종합!B$3:B$501,MATCH(ROW()-2,종합!$AB$3:$AB$501,0))&"","") -> (주) 에이아이웍스 | C7: =IFERROR(INDEX(종합!C$3:C$501,MATCH(ROW()-2,종합!$AB$3:$AB$501,0))&"","") -> O | D7: =IFERROR(INDEX(종합!D$3:D$501,MATCH(ROW()-2,종합!$AB$3:$AB$501,0))&"","") -> O | E7: =IFERROR(INDEX(종합!E$3:E$501,MATCH(ROW()-2,종합!$AB$3:$AB$501,0))&"","") -> O | F7: =IFERROR(INDEX(종합!F$3:F$501,MATCH(ROW()-2,종합!$AB$3:$AB$501,0))&"","") -> O | G7: =IFERROR(INDEX(종합!G$3:G$501,MATCH(ROW()-2,종합!$AB$3:$AB$501,0))&"","") -> 중소기업 | H7: =IFERROR(INDEX(종합!H$3:H$501,MATCH(ROW()-2,종합!$AB$3:$AB$501,0))&"","") -> 517-88-00087 | I7: =IFERROR(INDEX(종합!I$3:I$501,MATCH(ROW()-2,종합!$AB$3:$AB$501,0))&"","") -> 윤석원 | ... Z7: =IFERROR(INDEX(종합!Z$3:Z$501,MATCH(ROW()-2,종합!$AB$3:$AB$501,0))&"","") -> 010-4720-7721
A8: =IF(B8="","",ROW()-2) -> 6 | B8: =IFERROR(INDEX(종합!B$3:B$501,MATCH(ROW()-2,종합!$AB$3:$AB$501,0))&"","") -> 알서포트 주식회사 | C8: =IFERROR(INDEX(종합!C$3:C$501,MATCH(ROW()-2,종합!$AB$3:$AB$501,0))&"","") -> O | D8: =IFERROR(INDEX(종합!D$3:D$501,MATCH(ROW()-2,종합!$AB$3:$AB$501,0))&"","") -> O | E8: =IFERROR(INDEX(종합!E$3:E$501,MATCH(ROW()-2,종합!$AB$3:$AB$501,0))&"","") -> O | F8: =IFERROR(INDEX(종합!F$3:F$501,MATCH(ROW()-2,종합!$AB$3:$AB$501,0))&"","") -> O | G8: =IFERROR(INDEX(종합!G$3:G$501,MATCH(ROW()-2,종합!$AB$3:$AB$501,0))&"","") -> 중소기업 | H8: =IFERROR(INDEX(종합!H$3:H$501,MATCH(ROW()-2,종합!$AB$3:$AB$501,0))&"","") -> 114-86-82265 | I8: =IFERROR(INDEX(종합!I$3:I$501,MATCH(ROW()-2,종합!$AB$3:$AB$501,0))&"","") -> 서형수 | ... Z8: =IFERROR(INDEX(종합!Z$3:Z$501,MATCH(ROW()-2,종합!$AB$3:$AB$501,0))&"","") -> 010-4142-1220
A9: =IF(B9="","",ROW()-2) -> 7 | B9: =IFERROR(INDEX(종합!B$3:B$501,MATCH(ROW()-2,종합!$AB$3:$AB$501,0))&"","") -> 디밀리언 | C9: =IFERROR(INDEX(종합!C$3:C$501,MATCH(ROW()-2,종합!$AB$3:$AB$501,0))&"","") -> O | D9: =IFERROR(INDEX(종합!D$3:D$501,MATCH(ROW()-2,종합!$AB$3:$AB$501,0))&"","") -> O | E9: =IFERROR(INDEX(종합!E$3:E$501,MATCH(ROW()-2,종합!$AB$3:$AB$501,0))&"","") -> O | F9: =IFERROR(INDEX(종합!F$3:F$501,MATCH(ROW()-2,종합!$AB$3:$AB$501,0))&"","") | G9: =IFERROR(INDEX(종합!G$3:G$501,MATCH(ROW()-2,종합!$AB$3:$AB$501,0))&"","") -> 중소기업 | H9: =IFERROR(INDEX(종합!H$3:H$501,MATCH(ROW()-2,종합!$AB$3:$AB$501,0))&"","") -> 704-87-02815 | I9: =IFERROR(INDEX(종합!I$3:I$501,MATCH(ROW()-2,종합!$AB$3:$AB$501,0))&"","") -> 한요한 | ... Z9: =IFERROR(INDEX(종합!Z$3:Z$501,MATCH(ROW()-2,종합!$AB$3:$AB$501,0))&"","") -> 010-2375-9958
A10: =IF(B10="","",ROW()-2) -> 8 | B10: =IFERROR(INDEX(종합!B$3:B$501,MATCH(ROW()-2,종합!$AB$3:$AB$501,0))&"","") -> (주)오토마타 | C10: =IFERROR(INDEX(종합!C$3:C$501,MATCH(ROW()-2,종합!$AB$3:$AB$501,0))&"","") -> O | D10: =IFERROR(INDEX(종합!D$3:D$501,MATCH(ROW()-2,종합!$AB$3:$AB$501,0))&"","") | E10: =IFERROR(INDEX(종합!E$3:E$501,MATCH(ROW()-2,종합!$AB$3:$AB$501,0))&"","") | F10: =IFERROR(INDEX(종합!F$3:F$501,MATCH(ROW()-2,종합!$AB$3:$AB$501,0))&"","") | G10: =IFERROR(INDEX(종합!G$3:G$501,MATCH(ROW()-2,종합!$AB$3:$AB$501,0))&"","") -> 중소기업 | H10: =IFERROR(INDEX(종합!H$3:H$501,MATCH(ROW()-2,종합!$AB$3:$AB$501,0))&"","") -> 590-88-00990 | I10: =IFERROR(INDEX(종합!I$3:I$501,MATCH(ROW()-2,종합!$AB$3:$AB$501,0))&"","") -> 이민규 | ... Z10: =IFERROR(INDEX(종합!Z$3:Z$501,MATCH(ROW()-2,종합!$AB$3:$AB$501,0))&"","") -> 010-9517-1322
A11: =IF(B11="","",ROW()-2) -> 9 | B11: =IFERROR(INDEX(종합!B$3:B$501,MATCH(ROW()-2,종합!$AB$3:$AB$501,0))&"","") -> (주)한국인공지능검증원 | C11: =IFERROR(INDEX(종합!C$3:C$501,MATCH(ROW()-2,종합!$AB$3:$AB$501,0))&"","") -> O | D11: =IFERROR(INDEX(종합!D$3:D$501,MATCH(ROW()-2,종합!$AB$3:$AB$501,0))&"","") | E11: =IFERROR(INDEX(종합!E$3:E$501,MATCH(ROW()-2,종합!$AB$3:$AB$501,0))&"","") | F11: =IFERROR(INDEX(종합!F$3:F$501,MATCH(ROW()-2,종합!$AB$3:$AB$501,0))&"","") | G11: =IFERROR(INDEX(종합!G$3:G$501,MATCH(ROW()-2,종합!$AB$3:$AB$501,0))&"","") -> 중소기업 | H11: =IFERROR(INDEX(종합!H$3:H$501,MATCH(ROW()-2,종합!$AB$3:$AB$501,0))&"","") -> 880-81-02140 | I11: =IFERROR(INDEX(종합!I$3:I$501,MATCH(ROW()-2,종합!$AB$3:$AB$501,0))&"","") -> 강문정 | ... Z11: =IFERROR(INDEX(종합!Z$3:Z$501,MATCH(ROW()-2,종합!$AB$3:$AB$501,0))&"","") -> 010-9557-1287
A12: =IF(B12="","",ROW()-2) -> 10 | B12: =IFERROR(INDEX(종합!B$3:B$501,MATCH(ROW()-2,종합!$AB$3:$AB$501,0))&"","") -> (주)이지스 | C12: =IFERROR(INDEX(종합!C$3:C$501,MATCH(ROW()-2,종합!$AB$3:$AB$501,0))&"","") -> O | D12: =IFERROR(INDEX(종합!D$3:D$501,MATCH(ROW()-2,종합!$AB$3:$AB$501,0))&"","") | E12: =IFERROR(INDEX(종합!E$3:E$501,MATCH(ROW()-2,종합!$AB$3:$AB$501,0))&"","") | F12: =IFERROR(INDEX(종합!F$3:F$501,MATCH(ROW()-2,종합!$AB$3:$AB$501,0))&"","") | G12: =IFERROR(INDEX(종합!G$3:G$501,MATCH(ROW()-2,종합!$AB$3:$AB$501,0))&"","") -> 중소기업 | H12: =IFERROR(INDEX(종합!H$3:H$501,MATCH(ROW()-2,종합!$AB$3:$AB$501,0))&"","") -> 503-81-49156 | I12: =IFERROR(INDEX(종합!I$3:I$501,MATCH(ROW()-2,종합!$AB$3:$AB$501,0))&"","") -> 김성호 | ... Z12: =IFERROR(INDEX(종합!Z$3:Z$501,MATCH(ROW()-2,종합!$AB$3:$AB$501,0))&"","") -> 010-9904-1147
A13: =IF(B13="","",ROW()-2) -> 11 | B13: =IFERROR(INDEX(종합!B$3:B$501,MATCH(ROW()-2,종합!$AB$3:$AB$501,0))&"","") -> 칵테일아이오(주) | C13: =IFERROR(INDEX(종합!C$3:C$501,MATCH(ROW()-2,종합!$AB$3:$AB$501,0))&"","") -> O | D13: =IFERROR(INDEX(종합!D$3:D$501,MATCH(ROW()-2,종합!$AB$3:$AB$501,0))&"","") | E13: =IFERROR(INDEX(종합!E$3:E$501,MATCH(ROW()-2,종합!$AB$3:$AB$501,0))&"","") | F13: =IFERROR(INDEX(종합!F$3:F$501,MATCH(ROW()-2,종합!$AB$3:$AB$501,0))&"","") | G13: =IFERROR(INDEX(종합!G$3:G$501,MATCH(ROW()-2,종합!$AB$3:$AB$501,0))&"","") -> 중소기업 | H13: =IFERROR(INDEX(종합!H$3:H$501,MATCH(ROW()-2,종합!$AB$3:$AB$501,0))&"","") -> 759-88-00454 | I13: =IFERROR(INDEX(종합!I$3:I$501,MATCH(ROW()-2,종합!$AB$3:$AB$501,0))&"","") -> 이영수 | ... Z13: =IFERROR(INDEX(종합!Z$3:Z$501,MATCH(ROW()-2,종합!$AB$3:$AB$501,0))&"","") -> 010-8337-6611
A14: =IF(B14="","",ROW()-2) -> 12 | B14: =IFERROR(INDEX(종합!B$3:B$501,MATCH(ROW()-2,종합!$AB$3:$AB$501,0))&"","") -> (주)브로드웨이브 | C14: =IFERROR(INDEX(종합!C$3:C$501,MATCH(ROW()-2,종합!$AB$3:$AB$501,0))&"","") -> O | D14: =IFERROR(INDEX(종합!D$3:D$501,MATCH(ROW()-2,종합!$AB$3:$AB$501,0))&"","") -> O | E14: =IFERROR(INDEX(종합!E$3:E$501,MATCH(ROW()-2,종합!$AB$3:$AB$501,0))&"","") -> O | F14: =IFERROR(INDEX(종합!F$3:F$501,MATCH(ROW()-2,종합!$AB$3:$AB$501,0))&"","") | G14: =IFERROR(INDEX(종합!G$3:G$501,MATCH(ROW()-2,종합!$AB$3:$AB$501,0))&"","") -> 중소기업 | H14: =IFERROR(INDEX(종합!H$3:H$501,MATCH(ROW()-2,종합!$AB$3:$AB$501,0))&"","") -> 105-86-66766 | I14: =IFERROR(INDEX(종합!I$3:I$501,MATCH(ROW()-2,종합!$AB$3:$AB$501,0))&"","") -> 이태진 | ... Z14: =IFERROR(INDEX(종합!Z$3:Z$501,MATCH(ROW()-2,종합!$AB$3:$AB$501,0))&"","") -> 010-2357-2799
... A452: =IF(B452="","",ROW()-2) | B452: =IFERROR(INDEX(종합!B$3:B$501,MATCH(ROW()-2,종합!$AB$3:$AB$501,0))&"","") | C452: =IFERROR(INDEX(종합!C$3:C$501,MATCH(ROW()-2,종합!$AB$3:$AB$501,0))&"","") | D452: =IFERROR(INDEX(종합!D$3:D$501,MATCH(ROW()-2,종합!$AB$3:$AB$501,0))&"","") | E452: =IFERROR(INDEX(종합!E$3:E$501,MATCH(ROW()-2,종합!$AB$3:$AB$501,0))&"","") | F452: =IFERROR(INDEX(종합!F$3:F$501,MATCH(ROW()-2,종합!$AB$3:$AB$501,0))&"","") | G452: =IFERROR(INDEX(종합!G$3:G$501,MATCH(ROW()-2,종합!$AB$3:$AB$501,0))&"","") | H452: =IFERROR(INDEX(종합!H$3:H$501,MATCH(ROW()-2,종합!$AB$3:$AB$501,0))&"","") | I452: =IFERROR(INDEX(종합!I$3:I$501,MATCH(ROW()-2,종합!$AB$3:$AB$501,0))&"","") | ... Z452: =IFERROR(INDEX(종합!Z$3:Z$501,MATCH(ROW()-2,종합!$AB$3:$AB$501,0))&"","")

Sheet 산업분과
A1: 기업(기관) 정보 | O1: 활동 임원 | U1: 활동 실무
A2: No | B2: 회사(기관, 대학)명 | C2: 기술 | D2: 산업 | E2: 생태계 | F2: 안전·신뢰 | G2: 기업유형 | H2: 사업자등록번호 | I2: 대표자 | J2: 대표전화 | K2: 홈페이지 | L2: 이메일 주소 | M2: 주소 | N2: AI 전문 분야 및 보유기술·서비스(솔루션) | O2: 성명 | P2: 부서 | Q2: 직위/직책 | R2: 전화번호 | S2: 이메일 | T2: 휴대전화 번호 | U2: 성명 2 | V2: 부서 2 | W2: 직위/직책 2 | X2: 전화번호 2 | Y2: 이메일 2 | Z2: 휴대전화 번호 2
A3: =IF(B3="","",ROW()-2) -> 1 | B3: =IFERROR(INDEX(종합!B$3:B$501,MATCH(ROW()-2,종합!$AC$3:$AC$501,0))&"","") -> 주식회사 케이솔루션즈 | C3: =IFERROR(INDEX(종합!C$3:C$501,MATCH(ROW()-2,종합!$AC$3:$AC$501,0))&"","") | D3: =IFERROR(INDEX(종합!D$3:D$501,MATCH(ROW()-2,종합!$AC$3:$AC$501,0))&"","") -> O | E3: =IFERROR(INDEX(종합!E$3:E$501,MATCH(ROW()-2,종합!$AC$3:$AC$501,0))&"","") | F3: =IFERROR(INDEX(종합!F$3:F$501,MATCH(ROW()-2,종합!$AC$3:$AC$501,0))&"","") | G3: =IFERROR(INDEX(종합!G$3:G$501,MATCH(ROW()-2,종합!$AC$3:$AC$501,0))&"","") -> 중소기업 | H3: =IFERROR(INDEX(종합!H$3:H$501,MATCH(ROW()-2,종합!$AC$3:$AC$501,0))&"","") -> 134-87-20969 | I3: =IFERROR(INDEX(종합!I$3:I$501,MATCH(ROW()-2,종합!$AC$3:$AC$501,0))&"","") -> 김민수 | ... Z3: =IFERROR(INDEX(종합!Z$3:Z$501,MATCH(ROW()-2,종합!$AC$3:$AC$501,0))&"","") -> 010-4526-3280
A4: =IF(B4="","",ROW()-2) -> 2 | B4: =IFERROR(INDEX(종합!B$3:B$501,MATCH(ROW()-2,종합!$AC$3:$AC$501,0))&"","") -> 농업회사법인 (주)온팜 | C4: =IFERROR(INDEX(종합!C$3:C$501,MATCH(ROW()-2,종합!$AC$3:$AC$501,0))&"","") | D4: =IFERROR(INDEX(종합!D$3:D$501,MATCH(ROW()-2,종합!$AC$3:$AC$501,0))&"","") -> O | E4: =IFERROR(INDEX(종합!E$3:E$501,MATCH(ROW()-2,종합!$AC$3:$AC$501,0))&"","") | F4: =IFERROR(INDEX(종합!F$3:F$501,MATCH(ROW()-2,종합!$AC$3:$AC$501,0))&"","") | G4: =IFERROR(INDEX(종합!G$3:G$501,MATCH(ROW()-2,종합!$AC$3:$AC$501,0))&"","") -> 중소기업 | H4: =IFERROR(INDEX(종합!H$3:H$501,MATCH(ROW()-2,종합!$AC$3:$AC$501,0))&"","") -> 291-88-01904 | I4: =IFERROR(INDEX(종합!I$3:I$501,MATCH(ROW()-2,종합!$AC$3:$AC$501,0))&"","") -> 정원기 | ... Z4: =IFERROR(INDEX(종합!Z$3:Z$501,MATCH(ROW()-2,종합!$AC$3:$AC$501,0))&"","") -> 010-5481-0716
A5: =IF(B5="","",ROW()-2) -> 3 | B5: =IFERROR(INDEX(종합!B$3:B$501,MATCH(ROW()-2,종합!$AC$3:$AC$501,0))&"","") -> 에스큐케이 주식회사 | C5: =IFERROR(INDEX(종합!C$3:C$501,MATCH(ROW()-2,종합!$AC$3:$AC$501,0))&"","") | D5: =IFERROR(INDEX(종합!D$3:D$501,MATCH(ROW()-2,종합!$AC$3:$AC$501,0))&"","") -> O | E5: =IFERROR(INDEX(종합!E$3:E$501,MATCH(ROW()-2,종합!$AC$3:$AC$501,0))&"","") | F5: =IFERROR(INDEX(종합!F$3:F$501,MATCH(ROW()-2,종합!$AC$3:$AC$501,0))&"","") | G5: =IFERROR(INDEX(종합!G$3:G$501,MATCH(ROW()-2,종합!$AC$3:$AC$501,0))&"","") -> 중소기업 | H5: =IFERROR(INDEX(종합!H$3:H$501,MATCH(ROW()-2,종합!$AC$3:$AC$501,0))&"","") -> 316-87-02767 | I5: =IFERROR(INDEX(종합!I$3:I$501,MATCH(ROW()-2,종합!$AC$3:$AC$501,0))&"","") -> 손영제 | ... Z5: =IFERROR(INDEX(종합!Z$3:Z$501,MATCH(ROW()-2,종합!$AC$3:$AC$501,0))&"","") -> 010-2989-1979
A6: =IF(B6="","",ROW()-2) -> 4 | B6: =IFERROR(INDEX(종합!B$3:B$501,MATCH(ROW()-2,종합!$AC$3:$AC$501,0))&"","") -> 맨인블록 주식회사 | C6: =IFERROR(INDEX(종합!C$3:C$501,MATCH(ROW()-2,종합!$AC$3:$AC$501,0))&"","") | D6: =IFERROR(INDEX(종합!D$3:D$501,MATCH(ROW()-2,종합!$AC$3:$AC$501,0))&"","") -> O | E6: =IFERROR(INDEX(종합!E$3:E$501,MATCH(ROW()-2,종합!$AC$3:$AC$501,0))&"","") | F6: =IFERROR(INDEX(종합!F$3:F$501,MATCH(ROW()-2,종합!$AC$3:$AC$501,0))&"","") | G6: =IFERROR(INDEX(종합!G$3:G$501,MATCH(ROW()-2,종합!$AC$3:$AC$501,0))&"","") -> 중소기업 | H6: =IFERROR(INDEX(종합!H$3:H$501,MATCH(ROW()-2,종합!$AC$3:$AC$501,0))&"","") -> 731-86-02727 | I6: =IFERROR(INDEX(종합!I$3:I$501,MATCH(ROW()-2,종합!$AC$3:$AC$501,0))&"","") -> 박종형 | ... Z6: =IFERROR(INDEX(종합!Z$3:Z$501,MATCH(ROW()-2,종합!$AC$3:$AC$501,0))&"","") -> 010-9371-4756
A7: =IF(B7="","",ROW()-2) -> 5 | B7: =IFERROR(INDEX(종합!B$3:B$501,MATCH(ROW()-2,종합!$AC$3:$AC$501,0))&"","") -> 주식회사 에스에이티정보 | C7: =IFERROR(INDEX(종합!C$3:C$501,MATCH(ROW()-2,종합!$AC$3:$AC$501,0))&"","") | D7: =IFERROR(INDEX(종합!D$3:D$501,MATCH(ROW()-2,종합!$AC$3:$AC$501,0))&"","") -> O | E7: =IFERROR(INDEX(종합!E$3:E$501,MATCH(ROW()-2,종합!$AC$3:$AC$501,0))&"","") | F7: =IFERROR(INDEX(종합!F$3:F$501,MATCH(ROW()-2,종합!$AC$3:$AC$501,0))&"","") | G7: =IFERROR(INDEX(종합!G$3:G$501,MATCH(ROW()-2,종합!$AC$3:$AC$501,0))&"","") -> 중소기업 | H7: =IFERROR(INDEX(종합!H$3:H$501,MATCH(ROW()-2,종합!$AC$3:$AC$501,0))&"","") -> 119-86-26690 | I7: =IFERROR(INDEX(종합!I$3:I$501,MATCH(ROW()-2,종합!$AC$3:$AC$501,0))&"","") -> 오세용 | ... Z7: =IFERROR(INDEX(종합!Z$3:Z$501,MATCH(ROW()-2,종합!$AC$3:$AC$501,0))&"","") -> 010-9005-5197
A8: =IF(B8="","",ROW()-2) -> 6 | B8: =IFERROR(INDEX(종합!B$3:B$501,MATCH(ROW()-2,종합!$AC$3:$AC$501,0))&"","") -> 주식회사 씨에스리 | C8: =IFERROR(INDEX(종합!C$3:C$501,MATCH(ROW()-2,종합!$AC$3:$AC$501,0))&"","") | D8: =IFERROR(INDEX(종합!D$3:D$501,MATCH(ROW()-2,종합!$AC$3:$AC$501,0))&"","") -> O | E8: =IFERROR(INDEX(종합!E$3:E$501,MATCH(ROW()-2,종합!$AC$3:$AC$501,0))&"","") | F8: =IFERROR(INDEX(종합!F$3:F$501,MATCH(ROW()-2,종합!$AC$3:$AC$501,0))&"","") | G8: =IFERROR(INDEX(종합!G$3:G$501,MATCH(ROW()-2,종합!$AC$3:$AC$501,0))&"","") -> 중소기업 | H8: =IFERROR(INDEX(종합!H$3:H$501,MATCH(ROW()-2,종합!$AC$3:$AC$501,0))&"","") -> 105-87-86298 | I8: =IFERROR(INDEX(종합!I$3:I$501,MATCH(ROW()-2,종합!$AC$3:$AC$501,0))&"","") -> 이춘식 | ... Z8: =IFERROR(INDEX(종합!Z$3:Z$501,MATCH(ROW()-2,종합!$AC$3:$AC$501,0))&"","") -> 010-7362-6878
A9: =IF(B9="","",ROW()-2) -> 7 | B9: =IFERROR(INDEX(종합!B$3:B$501,MATCH(ROW()-2,종합!$AC$3:$AC$501,0))&"","") -> (주)사이냅소프트 | C9: =IFERROR(INDEX(종합!C$3:C$501,MATCH(ROW()-2,종합!$AC$3:$AC$501,0))&"","") | D9: =IFERROR(INDEX(종합!D$3:D$501,MATCH(ROW()-2,종합!$AC$3:$AC$501,0))&"","") -> O | E9: =IFERROR(INDEX(종합!E$3:E$501,MATCH(ROW()-2,종합!$AC$3:$AC$501,0))&"","") -> O | F9: =IFERROR(INDEX(종합!F$3:F$501,MATCH(ROW()-2,종합!$AC$3:$AC$501,0))&"","") | G9: =IFERROR(INDEX(종합!G$3:G$501,MATCH(ROW()-2,종합!$AC$3:$AC$501,0))&"","") -> 중소기업 | H9: =IFERROR(INDEX(종합!H$3:H$501,MATCH(ROW()-2,종합!$AC$3:$AC$501,0))&"","") -> 214-86-64984 | I9: =IFERROR(INDEX(종합!I$3:I$501,MATCH(ROW()-2,종합!$AC$3:$AC$501,0))&"","") -> 전경헌 | ... Z9: =IFERROR(INDEX(종합!Z$3:Z$501,MATCH(ROW()-2,종합!$AC$3:$AC$501,0))&"","") -> 010-3012-9110
A10: =IF(B10="","",ROW()-2) -> 8 | B10: =IFERROR(INDEX(종합!B$3:B$501,MATCH(ROW()-2,종합!$AC$3:$AC$501,0))&"","") -> 주식회사 데이터누리 | C10: =IFERROR(INDEX(종합!C$3:C$501,MATCH(ROW()-2,종합!$AC$3:$AC$501,0))&"","") | D10: =IFERROR(INDEX(종합!D$3:D$501,MATCH(ROW()-2,종합!$AC$3:$AC$501,0))&"","") -> O | E10: =IFERROR(INDEX(종합!E$3:E$501,MATCH(ROW()-2,종합!$AC$3:$AC$501,0))&"","") | F10: =IFERROR(INDEX(종합!F$3:F$501,MATCH(ROW()-2,종합!$AC$3:$AC$501,0))&"","") | G10: =IFERROR(INDEX(종합!G$3:G$501,MATCH(ROW()-2,종합!$AC$3:$AC$501,0))&"","") -> 중소기업 | H10: =IFERROR(INDEX(종합!H$3:H$501,MATCH(ROW()-2,종합!$AC$3:$AC$501,0))&"","") -> 199-81-01308 | I10: =IFERROR(INDEX(종합!I$3:I$501,MATCH(ROW()-2,종합!$AC$3:$AC$501,0))&"","") -> 강태원 | ... Z10: =IFERROR(INDEX(종합!Z$3:Z$501,MATCH(ROW()-2,종합!$AC$3:$AC$501,0))&"","") -> 010-6400-5413
A11: =IF(B11="","",ROW()-2) -> 9 | B11: =IFERROR(INDEX(종합!B$3:B$501,MATCH(ROW()-2,종합!$AC$3:$AC$501,0))&"","") -> 주식회사 와탭랩스 | C11: =IFERROR(INDEX(종합!C$3:C$501,MATCH(ROW()-2,종합!$AC$3:$AC$501,0))&"","") | D11: =IFERROR(INDEX(종합!D$3:D$501,MATCH(ROW()-2,종합!$AC$3:$AC$501,0))&"","") -> O | E11: =IFERROR(INDEX(종합!E$3:E$501,MATCH(ROW()-2,종합!$AC$3:$AC$501,0))&"","") | F11: =IFERROR(INDEX(종합!F$3:F$501,MATCH(ROW()-2,종합!$AC$3:$AC$501,0))&"","") | G11: =IFERROR(INDEX(종합!G$3:G$501,MATCH(ROW()-2,종합!$AC$3:$AC$501,0))&"","") -> 중소기업 | H11: =IFERROR(INDEX(종합!H$3:H$501,MATCH(ROW()-2,종합!$AC$3:$AC$501,0))&"","") -> 851-88-00084 | I11: =IFERROR(INDEX(종합!I$3:I$501,MATCH(ROW()-2,종합!$AC$3:$AC$501,0))&"","") -> 이동인 | ... Z11: =IFERROR(INDEX(종합!Z$3:Z$501,MATCH(ROW()-2,종합!$AC$3:$AC$501,0))&"","") -> 010-3255-6480
A12: =IF(B12="","",ROW()-2) -> 10 | B12: =IFERROR(INDEX(종합!B$3:B$501,MATCH(ROW()-2,종합!$AC$3:$AC$501,0))&"","") -> 트래시스(주) | C12: =IFERROR(INDEX(종합!C$3:C$501,MATCH(ROW()-2,종합!$AC$3:$AC$501,0))&"","") | D12: =IFERROR(INDEX(종합!D$3:D$501,MATCH(ROW()-2,종합!$AC$3:$AC$501,0))&"","") -> O | E12: =IFERROR(INDEX(종합!E$3:E$501,MATCH(ROW()-2,종합!$AC$3:$AC$501,0))&"","") | F12: =IFERROR(INDEX(종합!F$3:F$501,MATCH(ROW()-2,종합!$AC$3:$AC$501,0))&"","") | G12: =IFERROR(INDEX(종합!G$3:G$501,MATCH(ROW()-2,종합!$AC$3:$AC$501,0))&"","") -> 중소기업 | H12: =IFERROR(INDEX(종합!H$3:H$501,MATCH(ROW()-2,종합!$AC$3:$AC$501,0))&"","") -> 538-88-01948 | I12: =IFERROR(INDEX(종합!I$3:I$501,MATCH(ROW()-2,종합!$AC$3:$AC$501,0))&"","") -> 양국승 | ... Z12: =IFERROR(INDEX(종합!Z$3:Z$501,MATCH(ROW()-2,종합!$AC$3:$AC$501,0))&"","") -> 010-9942-9247
A13: =IF(B13="","",ROW()-2) -> 11 | B13: =IFERROR(INDEX(종합!B$3:B$501,MATCH(ROW()-2,종합!$AC$3:$AC$501,0))&"","") -> 주식회사 케파스 | C13: =IFERROR(INDEX(종합!C$3:C$501,MATCH(ROW()-2,종합!$AC$3:$AC$501,0))&"","") | D13: =IFERROR(INDEX(종합!D$3:D$501,MATCH(ROW()-2,종합!$AC$3:$AC$501,0))&"","") -> O | E13: =IFERROR(INDEX(종합!E$3:E$501,MATCH(ROW()-2,종합!$AC$3:$AC$501,0))&"","") | F13: =IFERROR(INDEX(종합!F$3:F$501,MATCH(ROW()-2,종합!$AC$3:$AC$501,0))&"","") | G13: =IFERROR(INDEX(종합!G$3:G$501,MATCH(ROW()-2,종합!$AC$3:$AC$501,0))&"","") -> 중소기업 | H13: =IFERROR(INDEX(종합!H$3:H$501,MATCH(ROW()-2,종합!$AC$3:$AC$501,0))&"","") -> 105-87-39024 | I13: =IFERROR(INDEX(종합!I$3:I$501,MATCH(ROW()-2,종합!$AC$3:$AC$501,0))&"","") -> 주성돈 | ... Z13: =IFERROR(INDEX(종합!Z$3:Z$501,MATCH(ROW()-2,종합!$AC$3:$AC$501,0))&"","") -> 010-2439-2727
A14: =IF(B14="","",ROW()-2) -> 12 | B14: =IFERROR(INDEX(종합!B$3:B$501,MATCH(ROW()-2,종합!$AC$3:$AC$501,0))&"","") -> 주식회사 랭코드 | C14: =IFERROR(INDEX(종합!C$3:C$501,MATCH(ROW()-2,종합!$AC$3:$AC$501,0))&"","") | D14: =IFERROR(INDEX(종합!D$3:D$501,MATCH(ROW()-2,종합!$AC$3:$AC$501,0))&"","") -> O | E14: =IFERROR(INDEX(종합!E$3:E$501,MATCH(ROW()-2,종합!$AC$3:$AC$501,0))&"","") | F14: =IFERROR(INDEX(종합!F$3:F$501,MATCH(ROW()-2,종합!$AC$3:$AC$501,0))&"","") | G14: =IFERROR(INDEX(종합!G$3:G$501,MATCH(ROW()-2,종합!$AC$3:$AC$501,0))&"","") -> 중소기업 | H14: =IFERROR(INDEX(종합!H$3:H$501,MATCH(ROW()-2,종합!$AC$3:$AC$501,0))&"","") -> 567-81-01670 | I14: =IFERROR(INDEX(종합!I$3:I$501,MATCH(ROW()-2,종합!$AC$3:$AC$501,0))&"","") -> 김민준 | ... Z14: =IFERROR(INDEX(종합!Z$3:Z$501,MATCH(ROW()-2,종합!$AC$3:$AC$501,0))&"","") -> 010-9555-3581
... A452: =IF(B452="","",ROW()-2) | B452: =IFERROR(INDEX(종합!B$3:B$501,MATCH(ROW()-2,종합!$AC$3:$AC$501,0))&"","") | C452: =IFERROR(INDEX(종합!C$3:C$501,MATCH(ROW()-2,종합!$AC$3:$AC$501,0))&"","") | D452: =IFERROR(INDEX(종합!D$3:D$501,MATCH(ROW()-2,종합!$AC$3:$AC$501,0))&"","") | E452: =IFERROR(INDEX(종합!E$3:E$501,MATCH(ROW()-2,종합!$AC$3:$AC$501,0))&"","") | F452: =IFERROR(INDEX(종합!F$3:F$501,MATCH(ROW()-2,종합!$AC$3:$AC$501,0))&"","") | G452: =IFERROR(INDEX(종합!G$3:G$501,MATCH(ROW()-2,종합!$AC$3:$AC$501,0))&"","") | H452: =IFERROR(INDEX(종합!H$3:H$501,MATCH(ROW()-2,종합!$AC$3:$AC$501,0))&"","") | I452: =IFERROR(INDEX(종합!I$3:I$501,MATCH(ROW()-2,종합!$AC$3:$AC$501,0))&"","") | ... Z452: =IFERROR(INDEX(종합!Z$3:Z$501,MATCH(ROW()-2,종합!$AC$3:$AC$501,0))&"","")

Sheet 생태계분과
A1: 기업(기관) 정보 | O1: 활동 임원 | U1: 활동 실무
A2: No | B2: 회사(기관, 대학)명 | C2: 기술 | D2: 산업 | E2: 생태계 | F2: 안전·신뢰 | G2: 기업유형 | H2: 사업자등록번호 | I2: 대표자 | J2: 대표전화 | K2: 홈페이지 | L2: 이메일 주소 | M2: 주소 | N2: AI 전문 분야 및 보유기술·서비스(솔루션) | O2: 성명 | P2: 부서 | Q2: 직위/직책 | R2: 전화번호 | S2: 이메일 | T2: 휴대전화 번호 | U2: 성명 2 | V2: 부서 2 | W2: 직위/직책 2 | X2: 전화번호 2 | Y2: 이메일 2 | Z2: 휴대전화 번호 2 | AA2: 비고
A3: =IF(B3="","",ROW()-2) -> 1 | B3: =IFERROR(INDEX(종합!B$3:B$501,MATCH(ROW()-2,종합!$AD$3:$AD$501,0))&"","") -> (주)사이냅소프트 | C3: =IFERROR(INDEX(종합!C$3:C$501,MATCH(ROW()-2,종합!$AD$3:$AD$501,0))&"","") | D3: =IFERROR(INDEX(종합!D$3:D$501,MATCH(ROW()-2,종합!$AD$3:$AD$501,0))&"","") -> O | E3: =IFERROR(INDEX(종합!E$3:E$501,MATCH(ROW()-2,종합!$AD$3:$AD$501,0))&"","") -> O | F3: =IFERROR(INDEX(종합!F$3:F$501,MATCH(ROW()-2,종합!$AD$3:$AD$501,0))&"","") | G3: =IFERROR(INDEX(종합!G$3:G$501,MATCH(ROW()-2,종합!$AD$3:$AD$501,0))&"","") -> 중소기업 | H3: =IFERROR(INDEX(종합!H$3:H$501,MATCH(ROW()-2,종합!$AD$3:$AD$501,0))&"","") -> 214-86-64984 | I3: =IFERROR(INDEX(종합!I$3:I$501,MATCH(ROW()-2,종합!$AD$3:$AD$501,0))&"","") -> 전경헌 | ... AA3: =IFERROR(INDEX(종합!AA$3:AA$501,MATCH(ROW()-2,종합!$AD$3:$AD$501,0))&"","")
A4: =IF(B4="","",ROW()-2) -> 2 | B4: =IFERROR(INDEX(종합!B$3:B$501,MATCH(ROW()-2,종합!$AD$3:$AD$501,0))&"","") -> 앵글컴퍼니 주식회사 | C4: =IFERROR(INDEX(종합!C$3:C$501,MATCH(ROW()-2,종합!$AD$3:$AD$501,0))&"","") -> O | D4: =IFERROR(INDEX(종합!D$3:D$501,MATCH(ROW()-2,종합!$AD$3:$AD$501,0))&"","") -> O | E4: =IFERROR(INDEX(종합!E$3:E$501,MATCH(ROW()-2,종합!$AD$3:$AD$501,0))&"","") -> O | F4: =IFERROR(INDEX(종합!F$3:F$501,MATCH(ROW()-2,종합!$AD$3:$AD$501,0))&"","") | G4: =IFERROR(INDEX(종합!G$3:G$501,MATCH(ROW()-2,종합!$AD$3:$AD$501,0))&"","") -> 중소기업 | H4: =IFERROR(INDEX(종합!H$3:H$501,MATCH(ROW()-2,종합!$AD$3:$AD$501,0))&"","") -> 172-88-02621 | I4: =IFERROR(INDEX(종합!I$3:I$501,MATCH(ROW()-2,종합!$AD$3:$AD$501,0))&"","") -> 박재범 | ... AA4: =IFERROR(INDEX(종합!AA$3:AA$501,MATCH(ROW()-2,종합!$AD$3:$AD$501,0))&"","")
A5: =IF(B5="","",ROW()-2) -> 3 | B5: =IFERROR(INDEX(종합!B$3:B$501,MATCH(ROW()-2,종합!$AD$3:$AD$501,0))&"","") -> (주)필라테크 | C5: =IFERROR(INDEX(종합!C$3:C$501,MATCH(ROW()-2,종합!$AD$3:$AD$501,0))&"","") | D5: =IFERROR(INDEX(종합!D$3:D$501,MATCH(ROW()-2,종합!$AD$3:$AD$501,0))&"","") -> O | E5: =IFERROR(INDEX(종합!E$3:E$501,MATCH(ROW()-2,종합!$AD$3:$AD$501,0))&"","") -> O | F5: =IFERROR(INDEX(종합!F$3:F$501,MATCH(ROW()-2,종합!$AD$3:$AD$501,0))&"","") | G5: =IFERROR(INDEX(종합!G$3:G$501,MATCH(ROW()-2,종합!$AD$3:$AD$501,0))&"","") -> 중소기업 | H5: =IFERROR(INDEX(종합!H$3:H$501,MATCH(ROW()-2,종합!$AD$3:$AD$501,0))&"","") -> 211-87-13620 | I5: =IFERROR(INDEX(종합!I$3:I$501,MATCH(ROW()-2,종합!$AD$3:$AD$501,0))&"","") -> 박동현 | ... AA5: =IFERROR(INDEX(종합!AA$3:AA$501,MATCH(ROW()-2,종합!$AD$3:$AD$501,0))&"","")
A6: =IF(B6="","",ROW()-2) -> 4 | B6: =IFERROR(INDEX(종합!B$3:B$501,MATCH(ROW()-2,종합!$AD$3:$AD$501,0))&"","") -> 주식회사 아이들 | C6: =IFERROR(INDEX(종합!C$3:C$501,MATCH(ROW()-2,종합!$AD$3:$AD$501,0))&"","") | D6: =IFERROR(INDEX(종합!D$3:D$501,MATCH(ROW()-2,종합!$AD$3:$AD$501,0))&"","") -> O | E6: =IFERROR(INDEX(종합!E$3:E$501,MATCH(ROW()-2,종합!$AD$3:$AD$501,0))&"","") -> O | F6: =IFERROR(INDEX(종합!F$3:F$501,MATCH(ROW()-2,종합!$AD$3:$AD$501,0))&"","") | G6: =IFERROR(INDEX(종합!G$3:G$501,MATCH(ROW()-2,종합!$AD$3:$AD$501,0))&"","") -> 중소기업 | H6: =IFERROR(INDEX(종합!H$3:H$501,MATCH(ROW()-2,종합!$AD$3:$AD$501,0))&"","") -> 820-81-02056 | I6: =IFERROR(INDEX(종합!I$3:I$501,MATCH(ROW()-2,종합!$AD$3:$AD$501,0))&"","") -> 허명구 | ... AA6: =IFERROR(INDEX(종합!AA$3:AA$501,MATCH(ROW()-2,종합!$AD$3:$AD$501,0))&"","")
A7: =IF(B7="","",ROW()-2) -> 5 | B7: =IFERROR(INDEX(종합!B$3:B$501,MATCH(ROW()-2,종합!$AD$3:$AD$501,0))&"","") -> 사단법인 한국디지털인증협회 | C7: =IFERROR(INDEX(종합!C$3:C$501,MATCH(ROW()-2,종합!$AD$3:$AD$501,0))&"","") | D7: =IFERROR(INDEX(종합!D$3:D$501,MATCH(ROW()-2,종합!$AD$3:$AD$501,0))&"","") -> O | E7: =IFERROR(INDEX(종합!E$3:E$501,MATCH(ROW()-2,종합!$AD$3:$AD$501,0))&"","") -> O | F7: =IFERROR(INDEX(종합!F$3:F$501,MATCH(ROW()-2,종합!$AD$3:$AD$501,0))&"","") | G7: =IFERROR(INDEX(종합!G$3:G$501,MATCH(ROW()-2,종합!$AD$3:$AD$501,0))&"","") -> 협회·단체 | H7: =IFERROR(INDEX(종합!H$3:H$501,MATCH(ROW()-2,종합!$AD$3:$AD$501,0))&"","") -> 894-82-00089 | I7: =IFERROR(INDEX(종합!I$3:I$501,MATCH(ROW()-2,종합!$AD$3:$AD$501,0))&"","") -> 이기혁 | ... AA7: =IFERROR(INDEX(종합!AA$3:AA$501,MATCH(ROW()-2,종합!$AD$3:$AD$501,0))&"","")
A8: =IF(B8="","",ROW()-2) -> 6 | B8: =IFERROR(INDEX(종합!B$3:B$501,MATCH(ROW()-2,종합!$AD$3:$AD$501,0))&"","") -> 주식회사 시넥스 | C8: =IFERROR(INDEX(종합!C$3:C$501,MATCH(ROW()-2,종합!$AD$3:$AD$501,0))&"","") -> O | D8: =IFERROR(INDEX(종합!D$3:D$501,MATCH(ROW()-2,종합!$AD$3:$AD$501,0))&"","") -> O | E8: =IFERROR(INDEX(종합!E$3:E$501,MATCH(ROW()-2,종합!$AD$3:$AD$501,0))&"","") -> O | F8: =IFERROR(INDEX(종합!F$3:F$501,MATCH(ROW()-2,종합!$AD$3:$AD$501,0))&"","") | G8: =IFERROR(INDEX(종합!G$3:G$501,MATCH(ROW()-2,종합!$AD$3:$AD$501,0))&"","") -> 중소기업 | H8: =IFERROR(INDEX(종합!H$3:H$501,MATCH(ROW()-2,종합!$AD$3:$AD$501,0))&"","") -> 744-87-03807 | I8: =IFERROR(INDEX(종합!I$3:I$501,MATCH(ROW()-2,종합!$AD$3:$AD$501,0))&"","") -> 이대은 | ... AA8: =IFERROR(INDEX(종합!AA$3:AA$501,MATCH(ROW()-2,종합!$AD$3:$AD$501,0))&"","")
A9: =IF(B9="","",ROW()-2) -> 7 | B9: =IFERROR(INDEX(종합!B$3:B$501,MATCH(ROW()-2,종합!$AD$3:$AD$501,0))&"","") -> (주) 에이아이웍스 | C9: =IFERROR(INDEX(종합!C$3:C$501,MATCH(ROW()-2,종합!$AD$3:$AD$501,0))&"","") -> O | D9: =IFERROR(INDEX(종합!D$3:D$501,MATCH(ROW()-2,종합!$AD$3:$AD$501,0))&"","") -> O | E9: =IFERROR(INDEX(종합!E$3:E$501,MATCH(ROW()-2,종합!$AD$3:$AD$501,0))&"","") -> O | F9: =IFERROR(INDEX(종합!F$3:F$501,MATCH(ROW()-2,종합!$AD$3:$AD$501,0))&"","") -> O | G9: =IFERROR(INDEX(종합!G$3:G$501,MATCH(ROW()-2,종합!$AD$3:$AD$501,0))&"","") -> 중소기업 | H9: =IFERROR(INDEX(종합!H$3:H$501,MATCH(ROW()-2,종합!$AD$3:$AD$501,0))&"","") -> 517-88-00087 | I9: =IFERROR(INDEX(종합!I$3:I$501,MATCH(ROW()-2,종합!$AD$3:$AD$501,0))&"","") -> 윤석원 | ... AA9: =IFERROR(INDEX(종합!AA$3:AA$501,MATCH(ROW()-2,종합!$AD$3:$AD$501,0))&"","")
A10: =IF(B10="","",ROW()-2) -> 8 | B10: =IFERROR(INDEX(종합!B$3:B$501,MATCH(ROW()-2,종합!$AD$3:$AD$501,0))&"","") -> 알서포트 주식회사 | C10: =IFERROR(INDEX(종합!C$3:C$501,MATCH(ROW()-2,종합!$AD$3:$AD$501,0))&"","") -> O | D10: =IFERROR(INDEX(종합!D$3:D$501,MATCH(ROW()-2,종합!$AD$3:$AD$501,0))&"","") -> O | E10: =IFERROR(INDEX(종합!E$3:E$501,MATCH(ROW()-2,종합!$AD$3:$AD$501,0))&"","") -> O | F10: =IFERROR(INDEX(종합!F$3:F$501,MATCH(ROW()-2,종합!$AD$3:$AD$501,0))&"","") -> O | G10: =IFERROR(INDEX(종합!G$3:G$501,MATCH(ROW()-2,종합!$AD$3:$AD$501,0))&"","") -> 중소기업 | H10: =IFERROR(INDEX(종합!H$3:H$501,MATCH(ROW()-2,종합!$AD$3:$AD$501,0))&"","") -> 114-86-82265 | I10: =IFERROR(INDEX(종합!I$3:I$501,MATCH(ROW()-2,종합!$AD$3:$AD$501,0))&"","") -> 서형수 | ... AA10: =IFERROR(INDEX(종합!AA$3:AA$501,MATCH(ROW()-2,종합!$AD$3:$AD$501,0))&"","")
A11: =IF(B11="","",ROW()-2) -> 9 | B11: =IFERROR(INDEX(종합!B$3:B$501,MATCH(ROW()-2,종합!$AD$3:$AD$501,0))&"","") -> 디밀리언 | C11: =IFERROR(INDEX(종합!C$3:C$501,MATCH(ROW()-2,종합!$AD$3:$AD$501,0))&"","") -> O | D11: =IFERROR(INDEX(종합!D$3:D$501,MATCH(ROW()-2,종합!$AD$3:$AD$501,0))&"","") -> O | E11: =IFERROR(INDEX(종합!E$3:E$501,MATCH(ROW()-2,종합!$AD$3:$AD$501,0))&"","") -> O | F11: =IFERROR(INDEX(종합!F$3:F$501,MATCH(ROW()-2,종합!$AD$3:$AD$501,0))&"","") | G11: =IFERROR(INDEX(종합!G$3:G$501,MATCH(ROW()-2,종합!$AD$3:$AD$501,0))&"","") -> 중소기업 | H11: =IFERROR(INDEX(종합!H$3:H$501,MATCH(ROW()-2,종합!$AD$3:$AD$501,0))&"","") -> 704-87-02815 | I11: =IFERROR(INDEX(종합!I$3:I$501,MATCH(ROW()-2,종합!$AD$3:$AD$501,0))&"","") -> 한요한 | ... AA11: =IFERROR(INDEX(종합!AA$3:AA$501,MATCH(ROW()-2,종합!$AD$3:$AD$501,0))&"","")
A12: =IF(B12="","",ROW()-2) -> 10 | B12: =IFERROR(INDEX(종합!B$3:B$501,MATCH(ROW()-2,종합!$AD$3:$AD$501,0))&"","") -> (주)브로드웨이브 | C12: =IFERROR(INDEX(종합!C$3:C$501,MATCH(ROW()-2,종합!$AD$3:$AD$501,0))&"","") -> O | D12: =IFERROR(INDEX(종합!D$3:D$501,MATCH(ROW()-2,종합!$AD$3:$AD$501,0))&"","") -> O | E12: =IFERROR(INDEX(종합!E$3:E$501,MATCH(ROW()-2,종합!$AD$3:$AD$501,0))&"","") -> O | F12: =IFERROR(INDEX(종합!F$3:F$501,MATCH(ROW()-2,종합!$AD$3:$AD$501,0))&"","") | G12: =IFERROR(INDEX(종합!G$3:G$501,MATCH(ROW()-2,종합!$AD$3:$AD$501,0))&"","") -> 중소기업 | H12: =IFERROR(INDEX(종합!H$3:H$501,MATCH(ROW()-2,종합!$AD$3:$AD$501,0))&"","") -> 105-86-66766 | I12: =IFERROR(INDEX(종합!I$3:I$501,MATCH(ROW()-2,종합!$AD$3:$AD$501,0))&"","") -> 이태진 | ... AA12: =IFERROR(INDEX(종합!AA$3:AA$501,MATCH(ROW()-2,종합!$AD$3:$AD$501,0))&"","")
A13: =IF(B13="","",ROW()-2) -> 11 | B13: =IFERROR(INDEX(종합!B$3:B$501,MATCH(ROW()-2,종합!$AD$3:$AD$501,0))&"","") -> (주)나라지식정보 | C13: =IFERROR(INDEX(종합!C$3:C$501,MATCH(ROW()-2,종합!$AD$3:$AD$501,0))&"","") -> O | D13: =IFERROR(INDEX(종합!D$3:D$501,MATCH(ROW()-2,종합!$AD$3:$AD$501,0))&"","") | E13: =IFERROR(INDEX(종합!E$3:E$501,MATCH(ROW()-2,종합!$AD$3:$AD$501,0))&"","") -> O | F13: =IFERROR(INDEX(종합!F$3:F$501,MATCH(ROW()-2,종합!$AD$3:$AD$501,0))&"","") -> O | G13: =IFERROR(INDEX(종합!G$3:G$501,MATCH(ROW()-2,종합!$AD$3:$AD$501,0))&"","") -> 중소기업 | H13: =IFERROR(INDEX(종합!H$3:H$501,MATCH(ROW()-2,종합!$AD$3:$AD$501,0))&"","") -> 105-87-16808 | I13: =IFERROR(INDEX(종합!I$3:I$501,MATCH(ROW()-2,종합!$AD$3:$AD$501,0))&"","") -> 손영호 | ... AA13: =IFERROR(INDEX(종합!AA$3:AA$501,MATCH(ROW()-2,종합!$AD$3:$AD$501,0))&"","")
